Workbook

Sheet Sumario
A1: Equipo | B1: Manager | C1: Saldo Inicial | D1: Gasto | E1: Ingresos | F1: Premios | G1: Saldo Actual | H1: Jugadores | I1: Valor Plantilla
A2: AdolfitoFlick | B2: Jose | C2: 100000000 | D2: =IFERROR(SUMIF(Fichajes!G:G,A2,Fichajes!I:I),0) -> 1363579862 | E2: =IFERROR(SUMIF(Fichajes!H:H,A2,Fichajes!I:I),0) -> 1302581395 | F2: =SUMIF(Premios!A:A,A2,Premios!E:E) -> 64700000 | G2: =C2-D2+E2+F2 -> 103701533 | H2: =COUNTIF(AdolfitoFlick!E:E,"X") -> 0 | I2: 244476931 | J2: =I2+G2 -> 348178464
A3: CrisGC14 | B3: Cristian | C3: 100000000 | D3: =IFERROR(SUMIF(Fichajes!G:G,A3,Fichajes!I:I),0) -> 637182397 | E3: =IFERROR(SUMIF(Fichajes!H:H,A3,Fichajes!I:I),0) -> 566505557 | F3: =SUMIF(Premios!A:A,A3,Premios!E:E) -> 55300000 | G3: =C3-D3+E3+F3 -> 84623160 | H3: =COUNTIF(CrisGC14!E:E,"X") -> 5 | I3: 208024347 | J3: =I3+G3 -> 292647507
A4: davidcdl10 | B4: Diez | C4: 100000000 | D4: =IFERROR(SUMIF(Fichajes!G:G,A4,Fichajes!I:I),0) -> 1313284059 | E4: =IFERROR(SUMIF(Fichajes!H:H,A4,Fichajes!I:I),0) -> 1274294160 | F4: =SUMIF(Premios!A:A,A4,Premios!E:E) -> 64700000 | G4: =C4-D4+E4+F4 -> 125710101 | H4: =COUNTIF(davidcdl10!E:E,"X") -> 7 | I4: 264054935 | J4: =I4+G4 -> 389765036
A5: Desteban19 | B5: David | C5: 100000000 | D5: =IFERROR(SUMIF(Fichajes!G:G,A5,Fichajes!I:I),0) -> 1971859169 | E5: =IFERROR(SUMIF(Fichajes!H:H,A5,Fichajes!I:I),0) -> 1931381128 | F5: =SUMIF(Premios!A:A,A5,Premios!E:E) -> 66700000 | G5: =C5-D5+E5+F5 -> 126221959 | H5: =COUNTIF(Desteban19!E:E,"X") -> 20 | I5: 353435221 | J5: =I5+G5 -> 479657180
A6: FC Capitan | B6: Dani Capitan | C6: 100000000 | D6: =IFERROR(SUMIF(Fichajes!G:G,A6,Fichajes!I:I),0) -> 1526797672 | E6: =IFERROR(SUMIF(Fichajes!H:H,A6,Fichajes!I:I),0) -> 1616953841 | F6: =SUMIF(Premios!A:A,A6,Premios!E:E) -> 64400000 | G6: =C6-D6+E6+F6 -> 254556169 | H6: =COUNTIF('FC Capitan'!E:E,"X") -> 1 | I6: 187973098 | J6: =I6+G6 -> 442529267
A7: FC Recreativo de Juerga | B7: Cano | C7: 100000000 | D7: =IFERROR(SUMIF(Fichajes!G:G,A7,Fichajes!I:I),0) -> 1246569425 | E7: =IFERROR(SUMIF(Fichajes!H:H,A7,Fichajes!I:I),0) -> 1297664581 | F7: =SUMIF(Premios!A:A,A7,Premios!E:E) -> 67400000 | G7: =C7-D7+E7+F7 -> 218495156 | H7: =COUNTIF('FC Recreativo de Juerga'!E:E,"X") -> 24 | I7: 235537339 | J7: =I7+G7 -> 454032495
A8: JMGuti14 | B8: Jona | C8: 100000000 | D8: =IFERROR(SUMIF(Fichajes!G:G,A8,Fichajes!I:I),0) -> 778796018 | E8: =IFERROR(SUMIF(Fichajes!H:H,A8,Fichajes!I:I),0) -> 720394620 | F8: =SUMIF(Premios!A:A,A8,Premios!E:E) -> 62000000 | G8: =C8-D8+E8+F8 -> 103598602 | H8: =COUNTIF(JMGuti14!E:E,"X") -> 9 | I8: 242665307 | J8: =I8+G8 -> 346263909
A9: Reivaj95 | B9: Javi | C9: 100000000 | D9: =IFERROR(SUMIF(Fichajes!G:G,A9,Fichajes!I:I),0) -> 2301792361 | E9: =IFERROR(SUMIF(Fichajes!H:H,A9,Fichajes!I:I),0) -> 2348240333 | F9: =SUMIF(Premios!A:A,A9,Premios!E:E) -> 82100000 | G9: =C9-D9+E9+F9 -> 228547972 | H9: =COUNTIF(Reivaj95!E:E,"X") -> 0 | I9: 353155756 | J9: =I9+G9 -> 581703728
A10: Shiquetito 9 | B10: Alvarito | C10: 100000000 | D10: =IFERROR(SUMIF(Fichajes!G:G,A10,Fichajes!I:I),0) -> 602185440 | E10: =IFERROR(SUMIF(Fichajes!H:H,A10,Fichajes!I:I),0) -> 572401121 | F10: =SUMIF(Premios!A:A,A10,Premios!E:E) -> 49100000 | G10: =C10-D10+E10+F10 -> 119315681 | H10: =COUNTIF('Shiquetito 9'!E:E,"X") -> 14 | I10: 224496375 | J10: =I10+G10 -> 343812056
A11: yandrak | B11: Diaz | C11: 100000000 | D11: =IFERROR(SUMIF(Fichajes!G:G,A11,Fichajes!I:I),0) -> 1207671008 | E11: =IFERROR(SUMIF(Fichajes!H:H,A11,Fichajes!I:I),0) -> 1140725189 | F11: =SUMIF(Premios!A:A,A11,Premios!E:E) -> 58400000 | G11: =C11-D11+E11+F11 -> 91454181 | H11: =COUNTIF(yandrak!E:E,"X") -> 3 | I11: 198920627 | J11: =I11+G11 -> 290374808
G14: =G3-G16-G17 -> 81123160
G16: 1500000
G17: 2000000

Sheet Nombres
A1: Jugador | B1: Jugador Fantasy | C1: Equipo | D1: Posicion | E1: FAN
A2: Christensen | B2: A. Christensen | C2: Barcelona | D2: DEF | E2: =OR(ISBLANK(B2),ISBLANK(A2)) -> FALSE
A3: Carreras | B3: A. F. Carreras | C3: Real Madrid | D3: DEF | E3: =OR(ISBLANK(B3),ISBLANK(A3)) -> FALSE
A4: Alvaro Nuñez | B4: Á. Núñez | C4: Elche | D4: DEF | E4: =OR(ISBLANK(B4),ISBLANK(A4)) -> FALSE
A5: Aarón | B5: Aarón | C5: Real Oviedo | D5: POR | E5: =OR(ISBLANK(B5),ISBLANK(A5)) -> FALSE
A6: Ez Abde | B6: Abde | C6: Betis | D6: DEL | E6: =OR(ISBLANK(B6),ISBLANK(A6)) -> FALSE
B7: Abdon | C7: Mallorca | D7: DEL | E7: =OR(ISBLANK(B7),ISBLANK(A7)) -> TRUE
B8: Abel Ruiz | C8: Girona | D8: DEL | E8: =OR(ISBLANK(B8),ISBLANK(A8)) -> TRUE
A9: Abqar | B9: Abqar | C9: Getafe | D9: DEF | E9: =OR(ISBLANK(B9),ISBLANK(A9)) -> FALSE
B10: Adam Boayar | C10: Elche | D10: MED | E10: =OR(ISBLANK(B10),ISBLANK(A10)) -> TRUE
B11: Adams | C11: Sevilla | D11: DEL | E11: =OR(ISBLANK(B11),ISBLANK(A11)) -> TRUE
A12: Adrian | B12: Adrián | C12: Betis | D12: POR | E12: =OR(ISBLANK(B12),ISBLANK(A12)) -> FALSE
B13: Adrián Molina | C13: Rayo | D13: POR | E13: =OR(ISBLANK(B13),ISBLANK(A13)) -> TRUE
A14: Affengruber | B14: Affengruber | C14: Elche | D14: DEF | E14: =OR(ISBLANK(B14),ISBLANK(A14)) -> FALSE
A15: Agirrezabala | B15: Agirrezabala | C15: Valencia | D15: POR | E15: =OR(ISBLANK(B15),ISBLANK(A15)) -> FALSE
A16: Agoume | B16: Agoume | C16: Sevilla | D16: MED | E16: =OR(ISBLANK(B16),ISBLANK(A16)) -> FALSE
A17: Aguado | B17: Aguado | C17: Elche | D17: MED | E17: =OR(ISBLANK(B17),ISBLANK(A17)) -> FALSE
B18: Ahijado | C18: Real Oviedo | D18: DEF | E18: =OR(ISBLANK(B18),ISBLANK(A18)) -> TRUE
B19: Aihen | C19: Real Sociedad | D19: DEF | E19: =OR(ISBLANK(B19),ISBLANK(A19)) -> TRUE
B20: Aimar Blázquez | C20: Valencia | D20: DEL | E20: =OR(ISBLANK(B20),ISBLANK(A20)) -> TRUE
A21: Aitor Fdez | B21: Aitor | C21: Osasuna | D21: POR | E21: =OR(ISBLANK(B21),ISBLANK(A21)) -> FALSE
B22: Aitor Fraga | C22: Real Sociedad | D22: POR | E22: =OR(ISBLANK(B22),ISBLANK(A22)) -> TRUE
A23: Akhomach | B23: Akhomach | C23: Villarreal | D23: DEL | E23: =OR(ISBLANK(B23),ISBLANK(A23)) -> FALSE
B24: Alaba | C24: Real Madrid | D24: DEF | E24: =OR(ISBLANK(B24),ISBLANK(A24)) -> TRUE
B25: Albert Niculaesei | C25: Elche | D25: DEF | E25: =OR(ISBLANK(B25),ISBLANK(A25)) -> TRUE
A26: Alberto F | B26: Alberto | C26: Sevilla | D26: POR | E26: =OR(ISBLANK(B26),ISBLANK(A26)) -> FALSE
B27: Alberto Risco | C27: Getafe | D27: MED | E27: =OR(ISBLANK(B27),ISBLANK(A27)) -> TRUE
A28: Alderete | B28: Alderete | C28: Getafe | D28: DEF | E28: =OR(ISBLANK(B28),ISBLANK(A28)) -> FALSE
A29: Rego | B29: Alejandro Rego | C29: Athletic | D29: DEF | E29: =OR(ISBLANK(B29),ISBLANK(A29)) -> FALSE
B30: Aleksandar Andreev | C30: Girona | D30: POR | E30: =OR(ISBLANK(B30),ISBLANK(A30)) -> TRUE
A31: Alemao | B31: Alemão | C31: Rayo | D31: DEL | E31: =OR(ISBLANK(B31),ISBLANK(A31)) -> FALSE
A32: Aleña | B32: Aleñá | C32: Alavés | D32: MED | E32: =OR(ISBLANK(B32),ISBLANK(A32)) -> FALSE
B33: Álex Costa | C33: Sevilla | D33: DEL | E33: =OR(ISBLANK(B33),ISBLANK(A33)) -> TRUE
B34: Álex Moreno | C34: Girona | D34: DEF | E34: =OR(ISBLANK(B34),ISBLANK(A34)) -> TRUE
A35: Trent | B35: Alexander-Arnold | C35: Real Madrid | D35: DEF | E35: =OR(ISBLANK(B35),ISBLANK(A35)) -> FALSE
A36: Alexis Sanchez | B36: Alexis | C36: Sevilla | D36: DEL | E36: =OR(ISBLANK(B36),ISBLANK(A36)) -> FALSE
A37: Alfon | B37: Alfon | C37: Sevilla | D37: DEL | E37: =OR(ISBLANK(B37),ISBLANK(A37)) -> FALSE
A38: Rahim | B38: Alhassane | C38: Real Oviedo | D38: DEF | E38: =OR(ISBLANK(B38),ISBLANK(A38)) -> FALSE
B39: Ali Houary | C39: Elche | D39: DEL | E39: =OR(ISBLANK(B39),ISBLANK(A39)) -> TRUE
A40: Almada | B40: Almada | C40: Atlético | D40: MED | E40: =OR(ISBLANK(B40),ISBLANK(A40)) -> FALSE
...

Sheet Fichajes
A1: ID | B1: Jugador Fantasy | C1: Posicion | D1: Equipo Real | E1: Jugador | F1: Fecha | G1: Comprador | H1: Vendedor | I1: Precio
A2: 1 | B2: =IF(ISERROR(VLOOKUP(E2,Nombres!A:D,2,FALSE)),"PROBLEMAAAAAA",VLOOKUP(E2,Nombres!A:D,2,FALSE)) -> Oroz | C2: =IF(ISERROR(VLOOKUP(E2,Nombres!A:D,4,FALSE)),"PROBLEMAAAAAA",VLOOKUP(E2,Nombres!A:D,4,FALSE)) -> MED | D2: =IF(ISERROR(VLOOKUP(E2,Nombres!A:D,3,FALSE)),"PROBLEMAAAAAA",VLOOKUP(E2,Nombres!A:D,3,FALSE)) -> Osasuna | E2: Aimar | F2: 45872 | G2: AdolfitoFlick | H2: Liga | I2: 0
A3: 2 | B3: =IF(ISERROR(VLOOKUP(E3,Nombres!A:D,2,FALSE)),"PROBLEMAAAAAA",VLOOKUP(E3,Nombres!A:D,2,FALSE)) -> Alderete | C3: =IF(ISERROR(VLOOKUP(E3,Nombres!A:D,4,FALSE)),"PROBLEMAAAAAA",VLOOKUP(E3,Nombres!A:D,4,FALSE)) -> DEF | D3: =IF(ISERROR(VLOOKUP(E3,Nombres!A:D,3,FALSE)),"PROBLEMAAAAAA",VLOOKUP(E3,Nombres!A:D,3,FALSE)) -> Getafe | E3: Alderete | F3: 45872 | G3: FC Recreativo de Juerga | H3: Liga | I3: 0
A4: 3 | B4: =IF(ISERROR(VLOOKUP(E4,Nombres!A:D,2,FALSE)),"PROBLEMAAAAAA",VLOOKUP(E4,Nombres!A:D,2,FALSE)) -> Almeida | C4: =IF(ISERROR(VLOOKUP(E4,Nombres!A:D,4,FALSE)),"PROBLEMAAAAAA",VLOOKUP(E4,Nombres!A:D,4,FALSE)) -> MED | D4: =IF(ISERROR(VLOOKUP(E4,Nombres!A:D,3,FALSE)),"PROBLEMAAAAAA",VLOOKUP(E4,Nombres!A:D,3,FALSE)) -> Valencia | E4: Almeida | F4: 45872 | G4: davidcdl10 | H4: Liga | I4: 0
A5: 4 | B5: =IF(ISERROR(VLOOKUP(E5,Nombres!A:D,2,FALSE)),"PROBLEMAAAAAA",VLOOKUP(E5,Nombres!A:D,2,FALSE)) -> Álvaro García | C5: =IF(ISERROR(VLOOKUP(E5,Nombres!A:D,4,FALSE)),"PROBLEMAAAAAA",VLOOKUP(E5,Nombres!A:D,4,FALSE)) -> MED | D5: =IF(ISERROR(VLOOKUP(E5,Nombres!A:D,3,FALSE)),"PROBLEMAAAAAA",VLOOKUP(E5,Nombres!A:D,3,FALSE)) -> Rayo | E5: Alvaro Garcia | F5: 45872 | G5: CrisGC14 | H5: Liga | I5: 0
A6: 5 | B6: =IF(ISERROR(VLOOKUP(E6,Nombres!A:D,2,FALSE)),"PROBLEMAAAAAA",VLOOKUP(E6,Nombres!A:D,2,FALSE)) -> Á. Núñez | C6: =IF(ISERROR(VLOOKUP(E6,Nombres!A:D,4,FALSE)),"PROBLEMAAAAAA",VLOOKUP(E6,Nombres!A:D,4,FALSE)) -> DEF | D6: =IF(ISERROR(VLOOKUP(E6,Nombres!A:D,3,FALSE)),"PROBLEMAAAAAA",VLOOKUP(E6,Nombres!A:D,3,FALSE)) -> Elche | E6: Alvaro Nuñez | F6: 45872 | G6: AdolfitoFlick | H6: Liga | I6: 0
A7: 6 | B7: =IF(ISERROR(VLOOKUP(E7,Nombres!A:D,2,FALSE)),"PROBLEMAAAAAA",VLOOKUP(E7,Nombres!A:D,2,FALSE)) -> Andrei | C7: =IF(ISERROR(VLOOKUP(E7,Nombres!A:D,4,FALSE)),"PROBLEMAAAAAA",VLOOKUP(E7,Nombres!A:D,4,FALSE)) -> DEF | D7: =IF(ISERROR(VLOOKUP(E7,Nombres!A:D,3,FALSE)),"PROBLEMAAAAAA",VLOOKUP(E7,Nombres!A:D,3,FALSE)) -> Rayo | E7: Andrei | F7: 45872 | G7: yandrak | H7: Liga | I7: 0
A8: 7 | B8: =IF(ISERROR(VLOOKUP(E8,Nombres!A:D,2,FALSE)),"PROBLEMAAAAAA",VLOOKUP(E8,Nombres!A:D,2,FALSE)) -> Arambarri | C8: =IF(ISERROR(VLOOKUP(E8,Nombres!A:D,4,FALSE)),"PROBLEMAAAAAA",VLOOKUP(E8,Nombres!A:D,4,FALSE)) -> MED | D8: =IF(ISERROR(VLOOKUP(E8,Nombres!A:D,3,FALSE)),"PROBLEMAAAAAA",VLOOKUP(E8,Nombres!A:D,3,FALSE)) -> Getafe | E8: Arambarri | F8: 45872 | G8: JMGuti14 | H8: Liga | I8: 0
A9: 8 | B9: =IF(ISERROR(VLOOKUP(E9,Nombres!A:D,2,FALSE)),"PROBLEMAAAAAA",VLOOKUP(E9,Nombres!A:D,2,FALSE)) -> Araújo | C9: =IF(ISERROR(VLOOKUP(E9,Nombres!A:D,4,FALSE)),"PROBLEMAAAAAA",VLOOKUP(E9,Nombres!A:D,4,FALSE)) -> DEF | D9: =IF(ISERROR(VLOOKUP(E9,Nombres!A:D,3,FALSE)),"PROBLEMAAAAAA",VLOOKUP(E9,Nombres!A:D,3,FALSE)) -> Barcelona | E9: Araujo | F9: 45872 | G9: FC Capitan | H9: Liga | I9: 0
A10: 9 | B10: =IF(ISERROR(VLOOKUP(E10,Nombres!A:D,2,FALSE)),"PROBLEMAAAAAA",VLOOKUP(E10,Nombres!A:D,2,FALSE)) -> Asano | C10: =IF(ISERROR(VLOOKUP(E10,Nombres!A:D,4,FALSE)),"PROBLEMAAAAAA",VLOOKUP(E10,Nombres!A:D,4,FALSE)) -> DEL | D10: =IF(ISERROR(VLOOKUP(E10,Nombres!A:D,3,FALSE)),"PROBLEMAAAAAA",VLOOKUP(E10,Nombres!A:D,3,FALSE)) -> Mallorca | E10: Asano | F10: 45872 | G10: FC Recreativo de Juerga | H10: Liga | I10: 0
A11: 10 | B11: =IF(ISERROR(VLOOKUP(E11,Nombres!A:D,2,FALSE)),"PROBLEMAAAAAA",VLOOKUP(E11,Nombres!A:D,2,FALSE)) -> Asencio | C11: =IF(ISERROR(VLOOKUP(E11,Nombres!A:D,4,FALSE)),"PROBLEMAAAAAA",VLOOKUP(E11,Nombres!A:D,4,FALSE)) -> DEF | D11: =IF(ISERROR(VLOOKUP(E11,Nombres!A:D,3,FALSE)),"PROBLEMAAAAAA",VLOOKUP(E11,Nombres!A:D,3,FALSE)) -> Real Madrid | E11: Asencio | F11: 45872 | G11: CrisGC14 | H11: Liga | I11: 0
A12: 11 | B12: =IF(ISERROR(VLOOKUP(E12,Nombres!A:D,2,FALSE)),"PROBLEMAAAAAA",VLOOKUP(E12,Nombres!A:D,2,FALSE)) -> Asprilla | C12: =IF(ISERROR(VLOOKUP(E12,Nombres!A:D,4,FALSE)),"PROBLEMAAAAAA",VLOOKUP(E12,Nombres!A:D,4,FALSE)) -> DEL | D12: =IF(ISERROR(VLOOKUP(E12,Nombres!A:D,3,FALSE)),"PROBLEMAAAAAA",VLOOKUP(E12,Nombres!A:D,3,FALSE)) -> Girona | E12: Asprilla | F12: 45872 | G12: FC Capitan | H12: Liga | I12: 0
A13: 12 | B13: =IF(ISERROR(VLOOKUP(E13,Nombres!A:D,2,FALSE)),"PROBLEMAAAAAA",VLOOKUP(E13,Nombres!A:D,2,FALSE)) -> Bade | C13: =IF(ISERROR(VLOOKUP(E13,Nombres!A:D,4,FALSE)),"PROBLEMAAAAAA",VLOOKUP(E13,Nombres!A:D,4,FALSE)) -> DEF | D13: =IF(ISERROR(VLOOKUP(E13,Nombres!A:D,3,FALSE)),"PROBLEMAAAAAA",VLOOKUP(E13,Nombres!A:D,3,FALSE)) -> Sevilla | E13: Bade | F13: 45872 | G13: davidcdl10 | H13: Liga | I13: 0
... A816: 815 | B816: =IF(ISERROR(VLOOKUP(E816,Nombres!A:D,2,FALSE)),"PROBLEMAAAAAA",VLOOKUP(E816,Nombres!A:D,2,FALSE)) -> Mastantuono | C816: =IF(ISERROR(VLOOKUP(E816,Nombres!A:D,4,FALSE)),"PROBLEMAAAAAA",VLOOKUP(E816,Nombres!A:D,4,FALSE)) -> DEL | D816: =IF(ISERROR(VLOOKUP(E816,Nombres!A:D,3,FALSE)),"PROBLEMAAAAAA",VLOOKUP(E816,Nombres!A:D,3,FALSE)) -> Real Madrid | E816: Mastantuono | F816: 45942 | G816: Shiquetito 9 | H816: Liga | I816: 53968850
A817: 816 | B817: =IF(ISERROR(VLOOKUP(E817,Nombres!A:D,2,FALSE)),"PROBLEMAAAAAA",VLOOKUP(E817,Nombres!A:D,2,FALSE)) -> Yuri | C817: =IF(ISERROR(VLOOKUP(E817,Nombres!A:D,4,FALSE)),"PROBLEMAAAAAA",VLOOKUP(E817,Nombres!A:D,4,FALSE)) -> DEF | D817: =IF(ISERROR(VLOOKUP(E817,Nombres!A:D,3,FALSE)),"PROBLEMAAAAAA",VLOOKUP(E817,Nombres!A:D,3,FALSE)) -> Athletic | E817: Yuri | F817: 45942 | G817: FC Recreativo de Juerga
A818: 817 | B818: =IF(ISERROR(VLOOKUP(E818,Nombres!A:D,2,FALSE)),"PROBLEMAAAAAA",VLOOKUP(E818,Nombres!A:D,2,FALSE)) -> Denis Suárez | C818: =IF(ISERROR(VLOOKUP(E818,Nombres!A:D,4,FALSE)),"PROBLEMAAAAAA",VLOOKUP(E818,Nombres!A:D,4,FALSE)) -> MED | D818: =IF(ISERROR(VLOOKUP(E818,Nombres!A:D,3,FALSE)),"PROBLEMAAAAAA",VLOOKUP(E818,Nombres!A:D,3,FALSE)) -> Alavés | E818: Denis Suarez | F818: 45942 | G818: Liga | H818: AdolfitoFlick | I818: 705614
A819: 818 | B819: =IF(ISERROR(VLOOKUP(E819,Nombres!A:D,2,FALSE)),"PROBLEMAAAAAA",VLOOKUP(E819,Nombres!A:D,2,FALSE)) -> Danjuma | C819: =IF(ISERROR(VLOOKUP(E819,Nombres!A:D,4,FALSE)),"PROBLEMAAAAAA",VLOOKUP(E819,Nombres!A:D,4,FALSE)) -> DEL | D819: =IF(ISERROR(VLOOKUP(E819,Nombres!A:D,3,FALSE)),"PROBLEMAAAAAA",VLOOKUP(E819,Nombres!A:D,3,FALSE)) -> Valencia | E819: Danjuma | F819: 45943 | G819: AdolfitoFlick | H819: davidcdl10 | I819: 23115355
A820: 819 | B820: =IF(ISERROR(VLOOKUP(E820,Nombres!A:D,2,FALSE)),"PROBLEMAAAAAA",VLOOKUP(E820,Nombres!A:D,2,FALSE)) -> André Silva | C820: =IF(ISERROR(VLOOKUP(E820,Nombres!A:D,4,FALSE)),"PROBLEMAAAAAA",VLOOKUP(E820,Nombres!A:D,4,FALSE)) -> DEL | D820: =IF(ISERROR(VLOOKUP(E820,Nombres!A:D,3,FALSE)),"PROBLEMAAAAAA",VLOOKUP(E820,Nombres!A:D,3,FALSE)) -> Elche | E820: Andre Silva | F820: 45943 | G820: AdolfitoFlick | H820: Reivaj95 | I820: 10100101
A821: 820 | B821: =IF(ISERROR(VLOOKUP(E821,Nombres!A:D,2,FALSE)),"PROBLEMAAAAAA",VLOOKUP(E821,Nombres!A:D,2,FALSE)) -> Rafa Marín | C821: =IF(ISERROR(VLOOKUP(E821,Nombres!A:D,4,FALSE)),"PROBLEMAAAAAA",VLOOKUP(E821,Nombres!A:D,4,FALSE)) -> DEF | D821: =IF(ISERROR(VLOOKUP(E821,Nombres!A:D,3,FALSE)),"PROBLEMAAAAAA",VLOOKUP(E821,Nombres!A:D,3,FALSE)) -> Villarreal | E821: Rafa Marin | F821: 45943 | G821: FC Capitan | H821: Liga | I821: 39261200
A822: 821 | B822: =IF(ISERROR(VLOOKUP(E822,Nombres!A:D,2,FALSE)),"PROBLEMAAAAAA",VLOOKUP(E822,Nombres!A:D,2,FALSE)) -> Vivian | C822: =IF(ISERROR(VLOOKUP(E822,Nombres!A:D,4,FALSE)),"PROBLEMAAAAAA",VLOOKUP(E822,Nombres!A:D,4,FALSE)) -> DEF | D822: =IF(ISERROR(VLOOKUP(E822,Nombres!A:D,3,FALSE)),"PROBLEMAAAAAA",VLOOKUP(E822,Nombres!A:D,3,FALSE)) -> Athletic | E822: Vivian | F822: 45943 | G822: FC Capitan | H822: Liga | I822: 34200833
A823: 822 | B823: =IF(ISERROR(VLOOKUP(E823,Nombres!A:D,2,FALSE)),"PROBLEMAAAAAA",VLOOKUP(E823,Nombres!A:D,2,FALSE)) -> Sow | C823: =IF(ISERROR(VLOOKUP(E823,Nombres!A:D,4,FALSE)),"PROBLEMAAAAAA",VLOOKUP(E823,Nombres!A:D,4,FALSE)) -> MED | D823: =IF(ISERROR(VLOOKUP(E823,Nombres!A:D,3,FALSE)),"PROBLEMAAAAAA",VLOOKUP(E823,Nombres!A:D,3,FALSE)) -> Sevilla | E823: Sow | F823: 45944 | G823: Shiquetito 9 | H823: davidcdl10 | I823: 2213460
A824: 823 | B824: =IF(ISERROR(VLOOKUP(E824,Nombres!A:D,2,FALSE)),"PROBLEMAAAAAA",VLOOKUP(E824,Nombres!A:D,2,FALSE)) -> Hugo Álvarez | C824: =IF(ISERROR(VLOOKUP(E824,Nombres!A:D,4,FALSE)),"PROBLEMAAAAAA",VLOOKUP(E824,Nombres!A:D,4,FALSE)) -> MED | D824: =IF(ISERROR(VLOOKUP(E824,Nombres!A:D,3,FALSE)),"PROBLEMAAAAAA",VLOOKUP(E824,Nombres!A:D,3,FALSE)) -> Celta | E824: Hugo Alvarez | F824: 45944 | G824: Shiquetito 9 | H824: davidcdl10 | I824: 6700000
A825: 824 | B825: =IF(ISERROR(VLOOKUP(E825,Nombres!A:D,2,FALSE)),"PROBLEMAAAAAA",VLOOKUP(E825,Nombres!A:D,2,FALSE)) -> Edu Expósito | C825: =IF(ISERROR(VLOOKUP(E825,Nombres!A:D,4,FALSE)),"PROBLEMAAAAAA",VLOOKUP(E825,Nombres!A:D,4,FALSE)) -> MED | D825: =IF(ISERROR(VLOOKUP(E825,Nombres!A:D,3,FALSE)),"PROBLEMAAAAAA",VLOOKUP(E825,Nombres!A:D,3,FALSE)) -> Espanyol | E825: Edu Exposito | F825: 45944 | G825: Shiquetito 9 | H825: Desteban19 | I825: 22875987
A826: 825 | B826: =IF(ISERROR(VLOOKUP(E826,Nombres!A:D,2,FALSE)),"PROBLEMAAAAAA",VLOOKUP(E826,Nombres!A:D,2,FALSE)) -> Román | C826: =IF(ISERROR(VLOOKUP(E826,Nombres!A:D,4,FALSE)),"PROBLEMAAAAAA",VLOOKUP(E826,Nombres!A:D,4,FALSE)) -> MED | D826: =IF(ISERROR(VLOOKUP(E826,Nombres!A:D,3,FALSE)),"PROBLEMAAAAAA",VLOOKUP(E826,Nombres!A:D,3,FALSE)) -> Celta | E826: Roman | F826: 45944 | G826: Liga | H826: JMGuti14 | I826: 420382
A827: 826 | B827: =IF(ISERROR(VLOOKUP(E827,Nombres!A:D,2,FALSE)),"PROBLEMAAAAAA",VLOOKUP(E827,Nombres!A:D,2,FALSE)) -> Mikautadze | C827: =IF(ISERROR(VLOOKUP(E827,Nombres!A:D,4,FALSE)),"PROBLEMAAAAAA",VLOOKUP(E827,Nombres!A:D,4,FALSE)) -> DEL | D827: =IF(ISERROR(VLOOKUP(E827,Nombres!A:D,3,FALSE)),"PROBLEMAAAAAA",VLOOKUP(E827,Nombres!A:D,3,FALSE)) -> Villarreal | E827: Mikautadze | F827: 45944 | G827: Shiquetito 9 | H827: FC Capitan | I827: 45100000
A828: 827 | B828: =IF(ISERROR(VLOOKUP(E828,Nombres!A:D,2,FALSE)),"PROBLEMAAAAAA",VLOOKUP(E828,Nombres!A:D,2,FALSE)) -> Morlanes | C828: =IF(ISERROR(VLOOKUP(E828,Nombres!A:D,4,FALSE)),"PROBLEMAAAAAA",VLOOKUP(E828,Nombres!A:D,4,FALSE)) -> MED | D828: =IF(ISERROR(VLOOKUP(E828,Nombres!A:D,3,FALSE)),"PROBLEMAAAAAA",VLOOKUP(E828,Nombres!A:D,3,FALSE)) -> Mallorca | E828: Morlanes | F828: 45944 | G828: davidcdl10 | H828: FC Capitan | I828: 1610010
A829: 828 | B829: =IF(ISERROR(VLOOKUP(E829,Nombres!A:D,2,FALSE)),"PROBLEMAAAAAA",VLOOKUP(E829,Nombres!A:D,2,FALSE)) -> Alexis | C829: =IF(ISERROR(VLOOKUP(E829,Nombres!A:D,4,FALSE)),"PROBLEMAAAAAA",VLOOKUP(E829,Nombres!A:D,4,FALSE)) -> DEL | D829: =IF(ISERROR(VLOOKUP(E829,Nombres!A:D,3,FALSE)),"PROBLEMAAAAAA",VLOOKUP(E829,Nombres!A:D,3,FALSE)) -> Sevilla | E829: Alexis Sanchez | F829: 45944 | G829: davidcdl10 | H829: FC Recreativo de Juerga | I829: 20677441
... A1060: 1059 | B1060: =IF(ISERROR(VLOOKUP(E1060,Nombres!A:D,2,FALSE)),"PROBLEMAAAAAA",VLOOKUP(E1060,Nombres!A:D,2,FALSE)) -> Abde | C1060: =IF(ISERROR(VLOOKUP(E1060,Nombres!A:D,4,FALSE)),"PROBLEMAAAAAA",VLOOKUP(E1060,Nombres!A:D,4,FALSE)) -> DEL | D1060: =IF(ISERROR(VLOOKUP(E1060,Nombres!A:D,3,FALSE)),"PROBLEMAAAAAA",VLOOKUP(E1060,Nombres!A:D,3,FALSE)) -> Betis | E1060: Ez Abde | F1060: 45974 | G1060: AdolfitoFlick | H1060: Reivaj95 | I1060: 43309964

Sheet Premios
A1: Equipo | B1: Jornada | C1: Posicion | D1: Puntos | E1: Premio
A2: davidcdl10 | B2: 1 | C2: =_xlfn.RANK.EQ(D2,D2:D11,0)+COUNTIF(D2:D2,D2)-1 -> 1 | D2: 68 | E2: 6800000
A3: Desteban19 | B3: 1 | C3: =_xlfn.RANK.EQ(D3,D2:D11,0)+COUNTIF(D2:D3,D3)-1 -> 2 | D3: 60 | E3: 6000000
A4: Reivaj95 | B4: 1 | C4: =_xlfn.RANK.EQ(D4,D2:D11,0)+COUNTIF(D2:D4,D4)-1 -> 3 | D4: 59 | E4: 5900000
A5: yandrak | B5: 1 | C5: =_xlfn.RANK.EQ(D5,D2:D11,0)+COUNTIF(D2:D5,D5)-1 -> 4 | D5: 54 | E5: 5400000
A6: AdolfitoFlick | B6: 1 | C6: =_xlfn.RANK.EQ(D6,D2:D11,0)+COUNTIF(D2:D6,D6)-1 -> 5 | D6: 53 | E6: 5300000
A7: Shiquetito 9 | B7: 1 | C7: =_xlfn.RANK.EQ(D7,D2:D11,0)+COUNTIF(D2:D7,D7)-1 -> 6 | D7: 49 | E7: 4900000
A8: JMGuti14 | B8: 1 | C8: =_xlfn.RANK.EQ(D8,D2:D11,0)+COUNTIF(D2:D8,D8)-1 -> 7 | D8: 46 | E8: 4600000
A9: CrisGC14 | B9: 1 | C9: =_xlfn.RANK.EQ(D9,D2:D11,0)+COUNTIF(D2:D9,D9)-1 -> 8 | D9: 36 | E9: 3600000
A10: FC Capitan | B10: 1 | C10: =_xlfn.RANK.EQ(D10,D2:D11,0)+COUNTIF(D2:D10,D10)-1 -> 9 | D10: 34 | E10: 3400000
A11: FC Recreativo de Juerga | B11: 1 | C11: =_xlfn.RANK.EQ(D11,D2:D11,0)+COUNTIF(D2:D11,D11)-1 -> 10 | D11: 22 | E11: 2200000
A12: FC Recreativo de Juerga | B12: 2 | C12: =_xlfn.RANK.EQ(D12,D12:D21,0)+COUNTIF(D12:D12,D12)-1 -> 6 | D12: 50 | E12: =D12*100000 -> 5000000
A13: yandrak | B13: 2 | C13: =_xlfn.RANK.EQ(D13,D12:D21,0)+COUNTIF(D12:D13,D13)-1 -> 7 | D13: 50 | E13: 5000000
A14: Shiquetito 9 | B14: 2 | C14: =_xlfn.RANK.EQ(D14,D12:D21,0)+COUNTIF(D12:D14,D14)-1 -> 9 | D14: 37 | E14: 3700000
A15: davidcdl10 | B15: 2 | C15: =_xlfn.RANK.EQ(D15,D12:D21,0)+COUNTIF(D12:D15,D15)-1 -> 2 | D15: 77 | E15: 7700000
A16: JMGuti14 | B16: 2 | C16: =_xlfn.RANK.EQ(D16,D12:D21,0)+COUNTIF(D12:D16,D16)-1 -> 10 | D16: 37 | E16: 3700000
A17: AdolfitoFlick | B17: 2 | C17: =_xlfn.RANK.EQ(D17,D12:D21,0)+COUNTIF(D12:D17,D17)-1 -> 8 | D17: 40 | E17: 4000000
A18: Desteban19 | B18: 2 | C18: =_xlfn.RANK.EQ(D18,D12:D21,0)+COUNTIF(D12:D18,D18)-1 -> 5 | D18: 52 | E18: 5200000
A19: FC Capitan | B19: 2 | C19: =_xlfn.RANK.EQ(D19,D12:D21,0)+COUNTIF(D12:D19,D19)-1 -> 4 | D19: 53 | E19: 5300000
A20: Reivaj95 | B20: 2 | C20: =_xlfn.RANK.EQ(D20,D12:D21,0)+COUNTIF(D12:D20,D20)-1 -> 1 | D20: 85 | E20: 8500000
A21: CrisGC14 | B21: 2 | C21: =_xlfn.RANK.EQ(D21,D12:D21,0)+COUNTIF(D12:D21,D21)-1 -> 3 | D21: 68 | E21: 6800000
A22: FC Recreativo de Juerga | B22: 3 | C22: =_xlfn.RANK.EQ(D22,D22:D31,0)+COUNTIF(D22:D22,D22)-1 -> 6 | D22: 48 | E22: 4800000
A23: yandrak | B23: 3 | C23: =_xlfn.RANK.EQ(D23,D22:D31,0)+COUNTIF(D22:D23,D23)-1 -> 3 | D23: 58 | E23: 5800000
A24: Shiquetito 9 | B24: 3 | C24: =_xlfn.RANK.EQ(D24,D22:D31,0)+COUNTIF(D22:D24,D24)-1 -> 4 | D24: 58 | E24: 5800000
A25: davidcdl10 | B25: 3 | C25: =_xlfn.RANK.EQ(D25,D22:D31,0)+COUNTIF(D22:D25,D25)-1 -> 10 | D25: 34 | E25: 3400000
A26: JMGuti14 | B26: 3 | C26: =_xlfn.RANK.EQ(D26,D22:D31,0)+COUNTIF(D22:D26,D26)-1 -> 1 | D26: 66 | E26: 6600000
A27: AdolfitoFlick | B27: 3 | C27: =_xlfn.RANK.EQ(D27,D22:D31,0)+COUNTIF(D22:D27,D27)-1 -> 5 | D27: 57 | E27: 5700000
A28: Desteban19 | B28: 3 | C28: =_xlfn.RANK.EQ(D28,D22:D31,0)+COUNTIF(D22:D28,D28)-1 -> 9 | D28: 38 | E28: 3800000
A29: FC Capitan | B29: 3 | C29: =_xlfn.RANK.EQ(D29,D22:D31,0)+COUNTIF(D22:D29,D29)-1 -> 7 | D29: 42 | E29: 4200000
A30: Reivaj95 | B30: 3 | C30: =_xlfn.RANK.EQ(D30,D22:D31,0)+COUNTIF(D22:D30,D30)-1 -> 2 | D30: 61 | E30: 6100000
A31: CrisGC14 | B31: 3 | C31: =_xlfn.RANK.EQ(D31,D22:D31,0)+COUNTIF(D22:D31,D31)-1 -> 8 | D31: 41 | E31: 4100000
A32: FC Recreativo de Juerga | B32: 4 | C32: =_xlfn.RANK.EQ(D32,D32:D41,0)+COUNTIF(D32:D32,D32)-1 -> 2 | D32: 67 | E32: 6700000
A33: yandrak | B33: 4 | C33: =_xlfn.RANK.EQ(D33,D32:D41,0)+COUNTIF(D32:D33,D33)-1 -> 3 | D33: 58 | E33: 5800000
A34: Shiquetito 9 | B34: 4 | C34: =_xlfn.RANK.EQ(D34,D32:D41,0)+COUNTIF(D32:D34,D34)-1 -> 9 | D34: 25 | E34: 2500000
A35: davidcdl10 | B35: 4 | C35: =_xlfn.RANK.EQ(D35,D32:D41,0)+COUNTIF(D32:D35,D35)-1 -> 6 | D35: 49 | E35: 4900000
A36: JMGuti14 | B36: 4 | C36: =_xlfn.RANK.EQ(D36,D32:D41,0)+COUNTIF(D32:D36,D36)-1 -> 5 | D36: 56 | E36: 5600000
A37: AdolfitoFlick | B37: 4 | C37: =_xlfn.RANK.EQ(D37,D32:D41,0)+COUNTIF(D32:D37,D37)-1 -> 8 | D37: 27 | E37: 2700000
A38: Desteban19 | B38: 4 | C38: =_xlfn.RANK.EQ(D38,D32:D41,0)+COUNTIF(D32:D38,D38)-1 -> 4 | D38: 57 | E38: 5700000
A39: FC Capitan | B39: 4 | C39: =_xlfn.RANK.EQ(D39,D32:D41,0)+COUNTIF(D32:D39,D39)-1 -> 7 | D39: 48 | E39: 4800000
A40: Reivaj95 | B40: 4 | C40: =_xlfn.RANK.EQ(D40,D32:D41,0)+COUNTIF(D32:D40,D40)-1 -> 1 | D40: 73 | E40: 7300000
...

Sheet Puntos
A1: Jornada | B1: Fecha | C1: Equipo | D1: Jugador | E1: Posicion | F1: Equipo Real | G1: Puntos | H1: Premio | I1: Posicion2 | J1: Jugador Fantasy
A2: 1 | B2: 45884 | C2: AdolfitoFlick | D2: Sivera | E2: POR | F2: Alavés | G2: 5 | H2: 500000 | I2: 1 | J2: Sivera
A3: 1 | B3: 45884 | C3: AdolfitoFlick | D3: Affengruber | E3: DEF | F3: Elche | G3: 7 | H3: 700000 | I3: 2 | J3: Affengruber
A4: 1 | B4: 45884 | C4: AdolfitoFlick | D4: Alex Balde | E4: DEF | F4: Barcelona | G4: 7 | H4: 700000 | I4: 2 | J4: Balde
A5: 1 | B5: 45884 | C5: AdolfitoFlick | D5: Alvaro Nuñez | E5: DEF | F5: Elche | G5: 6 | H5: 600000 | I5: 2 | J5: Á. Núñez
A6: 1 | B6: 45884 | C6: AdolfitoFlick | D6: Daley Blind | E6: DEF | F6: Girona | G6: 1 | H6: 100000 | I6: 2 | J6: Blind
A7: 1 | B7: 45884 | C7: AdolfitoFlick | D7: Luiz Felipe | E7: DEF | F7: Rayo | G7: 1 | H7: 100000 | I7: 2 | J7: Luiz Felipe
A8: 1 | B8: 45884 | C8: AdolfitoFlick | D8: Aimar | E8: MED | F8: Osasuna | G8: 3 | H8: 300000 | I8: 3 | J8: Oroz
A9: 1 | B9: 45884 | C9: AdolfitoFlick | D9: Darder | E9: MED | F9: Mallorca | G9: 3 | H9: 300000 | I9: 3 | J9: Darder
A10: 1 | B10: 45884 | C10: AdolfitoFlick | D10: Gueye | E10: MED | F10: Villarreal | G10: 15 | H10: 1500000 | I10: 3 | J10: P. Gueye
A11: 1 | B11: 45884 | C11: AdolfitoFlick | D11: Ivan Martin | E11: MED | F11: Girona | G11: 0 | H11: 0 | I11: 3 | J11: Iván Martín
A12: 1 | B12: 45884 | C12: AdolfitoFlick | D12: Gerard | E12: DEL | F12: Villarreal | G12: 6 | H12: 600000 | I12: 4 | J12: Gerard
A13: 1 | B13: 45884 | C13: CrisGC14 | D13: Unai Simon | E13: POR | F13: Athletic | G13: 3 | H13: 300000 | I13: 1 | J13: Unai Simón
... A881: 8 | B881: 45933 | C881: yandrak | D881: Vini Jr | E881: DEL | F881: Real Madrid | G881: 22 | H881: 2200000 | I881: 4 | J881: Vinicius
A882: 9 | B882: 45947 | C882: AdolfitoFlick | D882: Aarón | E882: =IF(ISERROR(VLOOKUP(D882,Nombres!A:D,4,FALSE)),"PROBLEMAAAAAA",VLOOKUP(D882,Nombres!A:D,4,FALSE)) -> POR | F882: =IF(ISERROR(VLOOKUP(D882,Nombres!A:D,3,FALSE)),"PROBLEMAAAAAA",VLOOKUP(D882,Nombres!A:D,3,FALSE)) -> Real Oviedo | G882: 9 | H882: =G882*100000 -> 900000 | I882: =IF(E882="POR",1,IF(E882="DEF",2,IF(E882="MED",3,4))) -> 1 | J882: =IF(ISERROR(VLOOKUP(D882,Nombres!A:D,2,FALSE)),"PROBLEMAAAAAA",VLOOKUP(D882,Nombres!A:D,2,FALSE)) -> Aarón
A883: 9 | B883: 45947 | C883: AdolfitoFlick | D883: Jeremy Toljan | E883: =IF(ISERROR(VLOOKUP(D883,Nombres!A:D,4,FALSE)),"PROBLEMAAAAAA",VLOOKUP(D883,Nombres!A:D,4,FALSE)) -> DEF | F883: =IF(ISERROR(VLOOKUP(D883,Nombres!A:D,3,FALSE)),"PROBLEMAAAAAA",VLOOKUP(D883,Nombres!A:D,3,FALSE)) -> Levante | G883: -2 | H883: =G883*100000 -> -200000 | I883: =IF(E883="POR",1,IF(E883="DEF",2,IF(E883="MED",3,4))) -> 2 | J883: =IF(ISERROR(VLOOKUP(D883,Nombres!A:D,2,FALSE)),"PROBLEMAAAAAA",VLOOKUP(D883,Nombres!A:D,2,FALSE)) -> Toljan
A884: 9 | B884: 45947 | C884: AdolfitoFlick | D884: Riedel | E884: =IF(ISERROR(VLOOKUP(D884,Nombres!A:D,4,FALSE)),"PROBLEMAAAAAA",VLOOKUP(D884,Nombres!A:D,4,FALSE)) -> DEF | F884: =IF(ISERROR(VLOOKUP(D884,Nombres!A:D,3,FALSE)),"PROBLEMAAAAAA",VLOOKUP(D884,Nombres!A:D,3,FALSE)) -> Espanyol | G884: 8 | H884: =G884*100000 -> 800000 | I884: =IF(E884="POR",1,IF(E884="DEF",2,IF(E884="MED",3,4))) -> 2 | J884: =IF(ISERROR(VLOOKUP(D884,Nombres!A:D,2,FALSE)),"PROBLEMAAAAAA",VLOOKUP(D884,Nombres!A:D,2,FALSE)) -> Riedel
A885: 9 | B885: 45947 | C885: AdolfitoFlick | D885: Carmona | E885: =IF(ISERROR(VLOOKUP(D885,Nombres!A:D,4,FALSE)),"PROBLEMAAAAAA",VLOOKUP(D885,Nombres!A:D,4,FALSE)) -> DEF | F885: =IF(ISERROR(VLOOKUP(D885,Nombres!A:D,3,FALSE)),"PROBLEMAAAAAA",VLOOKUP(D885,Nombres!A:D,3,FALSE)) -> Sevilla | G885: 6 | H885: =G885*100000 -> 600000 | I885: =IF(E885="POR",1,IF(E885="DEF",2,IF(E885="MED",3,4))) -> 2 | J885: =IF(ISERROR(VLOOKUP(D885,Nombres!A:D,2,FALSE)),"PROBLEMAAAAAA",VLOOKUP(D885,Nombres!A:D,2,FALSE)) -> Carmona
A886: 9 | B886: 45947 | C886: AdolfitoFlick | D886: Pacheco | E886: =IF(ISERROR(VLOOKUP(D886,Nombres!A:D,4,FALSE)),"PROBLEMAAAAAA",VLOOKUP(D886,Nombres!A:D,4,FALSE)) -> DEF | F886: =IF(ISERROR(VLOOKUP(D886,Nombres!A:D,3,FALSE)),"PROBLEMAAAAAA",VLOOKUP(D886,Nombres!A:D,3,FALSE)) -> Alavés | G886: 9 | H886: =G886*100000 -> 900000 | I886: =IF(E886="POR",1,IF(E886="DEF",2,IF(E886="MED",3,4))) -> 2 | J886: =IF(ISERROR(VLOOKUP(D886,Nombres!A:D,2,FALSE)),"PROBLEMAAAAAA",VLOOKUP(D886,Nombres!A:D,2,FALSE)) -> Pacheco
A887: 9 | B887: 45947 | C887: AdolfitoFlick | D887: German V | E887: =IF(ISERROR(VLOOKUP(D887,Nombres!A:D,4,FALSE)),"PROBLEMAAAAAA",VLOOKUP(D887,Nombres!A:D,4,FALSE)) -> MED | F887: =IF(ISERROR(VLOOKUP(D887,Nombres!A:D,3,FALSE)),"PROBLEMAAAAAA",VLOOKUP(D887,Nombres!A:D,3,FALSE)) -> Elche | G887: 5 | H887: =G887*100000 -> 500000 | I887: =IF(E887="POR",1,IF(E887="DEF",2,IF(E887="MED",3,4))) -> 3 | J887: =IF(ISERROR(VLOOKUP(D887,Nombres!A:D,2,FALSE)),"PROBLEMAAAAAA",VLOOKUP(D887,Nombres!A:D,2,FALSE)) -> Valera
A888: 9 | B888: 45947 | C888: AdolfitoFlick | D888: Samu Costa | E888: =IF(ISERROR(VLOOKUP(D888,Nombres!A:D,4,FALSE)),"PROBLEMAAAAAA",VLOOKUP(D888,Nombres!A:D,4,FALSE)) -> MED | F888: =IF(ISERROR(VLOOKUP(D888,Nombres!A:D,3,FALSE)),"PROBLEMAAAAAA",VLOOKUP(D888,Nombres!A:D,3,FALSE)) -> Mallorca | G888: 5 | H888: =G888*100000 -> 500000 | I888: =IF(E888="POR",1,IF(E888="DEF",2,IF(E888="MED",3,4))) -> 3 | J888: =IF(ISERROR(VLOOKUP(D888,Nombres!A:D,2,FALSE)),"PROBLEMAAAAAA",VLOOKUP(D888,Nombres!A:D,2,FALSE)) -> Samú
A889: 9 | B889: 45947 | C889: AdolfitoFlick | D889: Unai Lopez | E889: =IF(ISERROR(VLOOKUP(D889,Nombres!A:D,4,FALSE)),"PROBLEMAAAAAA",VLOOKUP(D889,Nombres!A:D,4,FALSE)) -> MED | F889: =IF(ISERROR(VLOOKUP(D889,Nombres!A:D,3,FALSE)),"PROBLEMAAAAAA",VLOOKUP(D889,Nombres!A:D,3,FALSE)) -> Rayo | G889: 11 | H889: =G889*100000 -> 1100000 | I889: =IF(E889="POR",1,IF(E889="DEF",2,IF(E889="MED",3,4))) -> 3 | J889: =IF(ISERROR(VLOOKUP(D889,Nombres!A:D,2,FALSE)),"PROBLEMAAAAAA",VLOOKUP(D889,Nombres!A:D,2,FALSE)) -> Unai López
A890: 9 | B890: 45947 | C890: AdolfitoFlick | D890: Lamine Yamal | E890: =IF(ISERROR(VLOOKUP(D890,Nombres!A:D,4,FALSE)),"PROBLEMAAAAAA",VLOOKUP(D890,Nombres!A:D,4,FALSE)) -> DEL | F890: =IF(ISERROR(VLOOKUP(D890,Nombres!A:D,3,FALSE)),"PROBLEMAAAAAA",VLOOKUP(D890,Nombres!A:D,3,FALSE)) -> Barcelona | G890: 10 | H890: =G890*100000 -> 1000000 | I890: =IF(E890="POR",1,IF(E890="DEF",2,IF(E890="MED",3,4))) -> 4 | J890: =IF(ISERROR(VLOOKUP(D890,Nombres!A:D,2,FALSE)),"PROBLEMAAAAAA",VLOOKUP(D890,Nombres!A:D,2,FALSE)) -> Yamal
A891: 9 | B891: 45947 | C891: AdolfitoFlick | D891: Danjuma | E891: =IF(ISERROR(VLOOKUP(D891,Nombres!A:D,4,FALSE)),"PROBLEMAAAAAA",VLOOKUP(D891,Nombres!A:D,4,FALSE)) -> DEL | F891: =IF(ISERROR(VLOOKUP(D891,Nombres!A:D,3,FALSE)),"PROBLEMAAAAAA",VLOOKUP(D891,Nombres!A:D,3,FALSE)) -> Valencia | G891: 6 | H891: =G891*100000 -> 600000 | I891: =IF(E891="POR",1,IF(E891="DEF",2,IF(E891="MED",3,4))) -> 4 | J891: =IF(ISERROR(VLOOKUP(D891,Nombres!A:D,2,FALSE)),"PROBLEMAAAAAA",VLOOKUP(D891,Nombres!A:D,2,FALSE)) -> Danjuma
A892: 9 | B892: 45947 | C892: AdolfitoFlick | D892: Cucho | E892: =IF(ISERROR(VLOOKUP(D892,Nombres!A:D,4,FALSE)),"PROBLEMAAAAAA",VLOOKUP(D892,Nombres!A:D,4,FALSE)) -> DEL | F892: =IF(ISERROR(VLOOKUP(D892,Nombres!A:D,3,FALSE)),"PROBLEMAAAAAA",VLOOKUP(D892,Nombres!A:D,3,FALSE)) -> Betis | G892: 0 | H892: =G892*100000 -> 0 | I892: =IF(E892="POR",1,IF(E892="DEF",2,IF(E892="MED",3,4))) -> 4 | J892: =IF(ISERROR(VLOOKUP(D892,Nombres!A:D,2,FALSE)),"PROBLEMAAAAAA",VLOOKUP(D892,Nombres!A:D,2,FALSE)) -> Cucho
A893: 10 | B893: 45947 | C893: AdolfitoFlick | D893: Radu | E893: =IF(ISERROR(VLOOKUP(D893,Nombres!A:D,4,FALSE)),"PROBLEMAAAAAA",VLOOKUP(D893,Nombres!A:D,4,FALSE)) -> POR | F893: =IF(ISERROR(VLOOKUP(D893,Nombres!A:D,3,FALSE)),"PROBLEMAAAAAA",VLOOKUP(D893,Nombres!A:D,3,FALSE)) -> Celta | G893: 5 | H893: =G893*100000 -> 500000 | I893: =IF(E893="POR",1,IF(E893="DEF",2,IF(E893="MED",3,4))) -> 1 | J893: =IF(ISERROR(VLOOKUP(D893,Nombres!A:D,2,FALSE)),"PROBLEMAAAAAA",VLOOKUP(D893,Nombres!A:D,2,FALSE)) -> Radu
... A1321: 12 | B1321: 45968 | C1321: yandrak | D1321: Pere Milla | E1321: =IF(ISERROR(VLOOKUP(D1321,Nombres!A:D,4,FALSE)),"PROBLEMAAAAAA",VLOOKUP(D1321,Nombres!A:D,4,FALSE)) -> DEL | F1321: =IF(ISERROR(VLOOKUP(D1321,Nombres!A:D,3,FALSE)),"PROBLEMAAAAAA",VLOOKUP(D1321,Nombres!A:D,3,FALSE)) -> Espanyol | G1321: 1 | H1321: =G1321*100000 -> 100000 | I1321: =IF(E1321="POR",1,IF(E1321="DEF",2,IF(E1321="MED",3,4))) -> 4 | J1321: =IF(ISERROR(VLOOKUP(D1321,Nombres!A:D,2,FALSE)),"PROBLEMAAAAAA",VLOOKUP(D1321,Nombres!A:D,2,FALSE)) -> Pere Milla

Sheet FC Recreativo de Juerga
A1: Indice | B1: FC Recreativo de Juerga
A2: Fichajes | K2: Ventas
A3: Posicion | B3: Jugador | C3: Fecha Compra | D3: Precio Compra | E3: Plantilla | K3: Posicion | L3: Jugador | M3: Fecha Venta | N3: Precio Venta | O3: Precio Compra | P3: Rentabilidad
A4: {=_xlfn._xlws.FILTER(Fichajes!C:C,Fichajes!G:G=B1)} -> DEF | B4: {=_xlfn._xlws.FILTER(Fichajes!B:B,Fichajes!G:G=B1)} -> Alderete | C4: {=_xlfn._xlws.FILTER(Fichajes!F:F,Fichajes!$G:$G=$B1)} -> 45872 | D4: {=_xlfn._xlws.FILTER(Fichajes!I:I,Fichajes!$G:$G=$B1)} -> 0 | E4: =IF(B4="","",IFERROR( IF( (VLOOKUP(B4,K:N,3,FALSE)) < C4, "X", "" ), "X") ) | K4: {=_xlfn._xlws.FILTER(Fichajes!B:B,Fichajes!$H:$H=B$1)} -> Carvajal | L4: {=_xlfn._xlws.FILTER(Fichajes!C:C,Fichajes!$H:$H=B$1)} -> DEF | M4: {=_xlfn._xlws.FILTER(Fichajes!F:F,Fichajes!$H:$H=B$1)} -> 45878 | N4: {=_xlfn._xlws.FILTER(Fichajes!I:I,Fichajes!$H:$H=B$1)} -> 27257064 | O4: =IF(ISBLANK(N4),"",VLOOKUP(K4,B:D,3,FALSE)) -> 0 | P4: =IF(ISBLANK(N4),"",N4-O4) -> 27257064
A5: DEL | B5: Asano | C5: 45872 | D5: 0 | E5: =IF(B5="","",IFERROR( IF( (VLOOKUP(B5,K:N,3,FALSE)) < C5, "X", "" ), "X") ) | K5: D. Llorente | L5: DEF | M5: 45878 | N5: 8482120 | O5: =IF(ISBLANK(N5),"",VLOOKUP(K5,B:D,3,FALSE)) -> 0 | P5: =IF(ISBLANK(N5),"",N5-O5) -> 8482120
A6: DEL | B6: Bakambu | C6: 45872 | D6: 0 | E6: =IF(B6="","",IFERROR( IF( (VLOOKUP(B6,K:N,3,FALSE)) < C6, "X", "" ), "X") ) | K6: Alderete | L6: DEF | M6: 45879 | N6: 10527479 | O6: =IF(ISBLANK(N6),"",VLOOKUP(K6,B:D,3,FALSE)) -> 0 | P6: =IF(ISBLANK(N6),"",N6-O6) -> 10527479
A7: DEF | B7: Carvajal | C7: 45872 | D7: 0 | E7: =IF(B7="","",IFERROR( IF( (VLOOKUP(B7,K:N,3,FALSE)) < C7, "X", "" ), "X") ) | K7: Van de Beek | L7: MED | M7: 45879 | N7: 3909069 | O7: =IF(ISBLANK(N7),"",VLOOKUP(K7,B:D,3,FALSE)) -> 0 | P7: =IF(ISBLANK(N7),"",N7-O7) -> 3909069
A8: DEF | B8: David López | C8: 45872 | D8: 0 | E8: =IF(B8="","",IFERROR( IF( (VLOOKUP(B8,K:N,3,FALSE)) < C8, "X", "" ), "X") ) | K8: Ejuke | L8: DEL | M8: 45881 | N8: 4000000 | O8: =IF(ISBLANK(N8),"",VLOOKUP(K8,B:D,3,FALSE)) -> 0 | P8: =IF(ISBLANK(N8),"",N8-O8) -> 4000000
A9: DEL | B9: Ejuke | C9: 45872 | D9: 0 | E9: =IF(B9="","",IFERROR( IF( (VLOOKUP(B9,K:N,3,FALSE)) < C9, "X", "" ), "X") ) | K9: Bakambu | L9: DEL | M9: 45883 | N9: 3345761 | O9: =IF(ISBLANK(N9),"",VLOOKUP(K9,B:D,3,FALSE)) -> 0 | P9: =IF(ISBLANK(N9),"",N9-O9) -> 3345761
A10: MED | B10: Guridi | C10: 45872 | D10: 0 | E10: =IF(B10="","",IFERROR( IF( (VLOOKUP(B10,K:N,3,FALSE)) < C10, "X", "" ), "X") ) | K10: Traore | L10: DEF | M10: 45883 | N10: 7269464 | O10: =IF(ISBLANK(N10),"",VLOOKUP(K10,B:D,3,FALSE)) -> 0 | P10: =IF(ISBLANK(N10),"",N10-O10) -> 7269464
A11: POR | B11: Leo Román | C11: 45872 | D11: 0 | E11: =IF(B11="","",IFERROR( IF( (VLOOKUP(B11,K:N,3,FALSE)) < C11, "X", "" ), "X") ) | K11: Leo Román | L11: POR | M11: 45887 | N11: 10938553 | O11: =IF(ISBLANK(N11),"",VLOOKUP(K11,B:D,3,FALSE)) -> 0 | P11: =IF(ISBLANK(N11),"",N11-O11) -> 10938553
A12: DEF | B12: D. Llorente | C12: 45872 | D12: 0 | E12: =IF(B12="","",IFERROR( IF( (VLOOKUP(B12,K:N,3,FALSE)) < C12, "X", "" ), "X") ) | K12: Muriqi | L12: DEL | M12: 45887 | N12: 27117936 | O12: =IF(ISBLANK(N12),"",VLOOKUP(K12,B:D,3,FALSE)) -> 36787048 | P12: =IF(ISBLANK(N12),"",N12-O12) -> -9669112
A13: MED | B13: Moncayola | C13: 45872 | D13: 0 | E13: =IF(B13="","",IFERROR( IF( (VLOOKUP(B13,K:N,3,FALSE)) < C13, "X", "" ), "X") ) | K13: Terrats | L13: MED | M13: 45887 | N13: 8502173 | O13: =IF(ISBLANK(N13),"",VLOOKUP(K13,B:D,3,FALSE)) -> 0 | P13: =IF(ISBLANK(N13),"",N13-O13) -> 8502173
A14: MED | B14: Terrats | C14: 45872 | D14: 0 | E14: =IF(B14="","",IFERROR( IF( (VLOOKUP(B14,K:N,3,FALSE)) < C14, "X", "" ), "X") ) | K14: Thomas | L14: MED | M14: 45889 | N14: 13815509 | O14: =IF(ISBLANK(N14),"",VLOOKUP(K14,B:D,3,FALSE)) -> 20000001 | P14: =IF(ISBLANK(N14),"",N14-O14) -> -6184492
A15: MED | B15: Torró | C15: 45872 | D15: 0 | E15: =IF(B15="","",IFERROR( IF( (VLOOKUP(B15,K:N,3,FALSE)) < C15, "X", "" ), "X") ) | K15: Balliu | L15: DEF | M15: 45891 | N15: 3427255 | O15: =IF(ISBLANK(N15),"",VLOOKUP(K15,B:D,3,FALSE)) -> 9500010 | P15: =IF(ISBLANK(N15),"",N15-O15) -> -6072755
A16: DEF | B16: Traore | C16: 45872 | D16: 0 | E16: =IF(B16="","",IFERROR( IF( (VLOOKUP(B16,K:N,3,FALSE)) < C16, "X", "" ), "X") ) | K16: Asano | L16: DEL | M16: 45895 | N16: 2247494 | O16: =IF(ISBLANK(N16),"",VLOOKUP(K16,B:D,3,FALSE)) -> 0 | P16: =IF(ISBLANK(N16),"",N16-O16) -> 2247494
... A48: MED | B48: R. de Galarreta | C48: 45917 | D48: 15593430 | E48: =IF(B48="","",IFERROR( IF( (VLOOKUP(B48,K:N,3,FALSE)) < C48, "X", "" ), "X") ) -> X | K48: Barrenetxea | L48: MED | M48: 45938 | N48: 32736001 | O48: =IF(ISBLANK(N48),"",VLOOKUP(K48,B:D,3,FALSE)) -> 5678911 | P48: =IF(ISBLANK(N48),"",N48-O48) -> 27057090
A49: MED | B49: Juanlu | C49: 45918 | D49: 6542165 | E49: =IF(B49="","",IFERROR( IF( (VLOOKUP(B49,K:N,3,FALSE)) < C49, "X", "" ), "X") ) | K49: Iván Martín | L49: MED | M49: 45940 | N49: 3834030
A50: DEL | B50: Víctor Muñoz | C50: 45918 | D50: 3987785 | E50: =IF(B50="","",IFERROR( IF( (VLOOKUP(B50,K:N,3,FALSE)) < C50, "X", "" ), "X") ) | K50: Alexis | L50: DEL | M50: 45944 | N50: 20677441
A51: DEF | B51: Militão | C51: 45919 | D51: 45865641 | E51: =IF(B51="","",IFERROR( IF( (VLOOKUP(B51,K:N,3,FALSE)) < C51, "X", "" ), "X") ) | K51: Etta Eyong | L51: DEL | M51: 45945 | N51: 110031134
A52: MED | B52: Febas | C52: 45922 | D52: 8210100 | E52: =IF(B52="","",IFERROR( IF( (VLOOKUP(B52,K:N,3,FALSE)) < C52, "X", "" ), "X") ) | K52: Azpilicueta | L52: DEF | M52: 45948 | N52: 5692561
A53: MED | B53: Lozano | C53: 45922 | D53: 3210000 | E53: =IF(B53="","",IFERROR( IF( (VLOOKUP(B53,K:N,3,FALSE)) < C53, "X", "" ), "X") ) | K53: Torró | L53: MED | M53: 45948 | N53: 2823674
A54: MED | B54: Barrenetxea | C54: 45924 | D54: 19369067 | E54: =IF(B54="","",IFERROR( IF( (VLOOKUP(B54,K:N,3,FALSE)) < C54, "X", "" ), "X") ) -> X | K54: Pépé | L54: DEL | M54: 45950 | N54: 91241452
A55: DEF | B55: Veiga | C55: 45924 | D55: 16128445 | E55: =IF(B55="","",IFERROR( IF( (VLOOKUP(B55,K:N,3,FALSE)) < C55, "X", "" ), "X") ) -> X | K55: Lozano | L55: MED | M55: 45953 | N55: 10014326
A56: DEF | B56: Vertrouwd | C56: 45924 | D56: 625059 | E56: =IF(B56="","",IFERROR( IF( (VLOOKUP(B56,K:N,3,FALSE)) < C56, "X", "" ), "X") ) -> X | K56: Febas | L56: MED | M56: 45953 | N56: 23210100
A57: DEL | B57: Etta Eyong | C57: 45928 | D57: 65117539 | E57: =IF(B57="","",IFERROR( IF( (VLOOKUP(B57,K:N,3,FALSE)) < C57, "X", "" ), "X") ) -> X | K57: N. Williams | L57: DEL | M57: 45957 | N57: 89423295
A58: DEL | B58: I. Williams | C58: 45928 | D58: 34309065 | E58: =IF(B58="","",IFERROR( IF( (VLOOKUP(B58,K:N,3,FALSE)) < C58, "X", "" ), "X") ) | K58: Luis Milla | L58: MED | M58: 45959 | N58: 90222396
A59: DEF | B59: Tenaglia | C59: 45916 | D59: 17000000 | E59: =IF(B59="","",IFERROR( IF( (VLOOKUP(B59,K:N,3,FALSE)) < C59, "X", "" ), "X") ) | K59: Manu Sánchez | L59: DEF | M59: 45960 | N59: 2160657
A60: MED | B60: Luis Milla | C60: 45930 | D60: 45988103 | E60: =IF(B60="","",IFERROR( IF( (VLOOKUP(B60,K:N,3,FALSE)) < C60, "X", "" ), "X") ) | K60: C. Álvarez | L60: MED | M60: 45960 | N60: 26980873
... A64: MED | B64: C. Álvarez | C64: 45934 | D64: 15411401 | E64: =IF(B64="","",IFERROR( IF( (VLOOKUP(B64,K:N,3,FALSE)) < C64, "X", "" ), "X") ) | K64: Natan | L64: DEF | M64: 45973 | N64: 44480506
A65: DEL | B65: Roberto | C65: 45936 | D65: 11087545 | E65: =IF(B65="","",IFERROR( IF( (VLOOKUP(B65,K:N,3,FALSE)) < C65, "X", "" ), "X") ) -> X
A66: DEF | B66: Valentín Gómez | C66: 45939 | D66: 2863699 | E66: =IF(B66="","",IFERROR( IF( (VLOOKUP(B66,K:N,3,FALSE)) < C66, "X", "" ), "X") )
A67: DEF | B67: Yuri | C67: 45942 | D67: 0 | E67: =IF(B67="","",IFERROR( IF( (VLOOKUP(B67,K:N,3,FALSE)) < C67, "X", "" ), "X") ) -> X
A68: MED | B68: Herrera | C68: 45944 | D68: 2651124 | E68: =IF(B68="","",IFERROR( IF( (VLOOKUP(B68,K:N,3,FALSE)) < C68, "X", "" ), "X") )
A69: DEL | B69: Boyé | C69: 45945 | D69: 2506689 | E69: =IF(B69="","",IFERROR( IF( (VLOOKUP(B69,K:N,3,FALSE)) < C69, "X", "" ), "X") ) -> X
A70: DEL | B70: Pépé | C70: 45945 | D70: 91296567 | E70: =IF(B70="","",IFERROR( IF( (VLOOKUP(B70,K:N,3,FALSE)) < C70, "X", "" ), "X") )
A71: DEF | B71: Manu Sánchez | C71: 45946 | D71: 2160657 | E71: =IF(B71="","",IFERROR( IF( (VLOOKUP(B71,K:N,3,FALSE)) < C71, "X", "" ), "X") )
A72: DEF | B72: Jonny | C72: 45948 | D72: 7045151 | E72: =IF(B72="","",IFERROR( IF( (VLOOKUP(B72,K:N,3,FALSE)) < C72, "X", "" ), "X") ) -> X
A73: DEL | B73: N. Williams | C73: 45949 | D73: 98000052 | E73: =IF(B73="","",IFERROR( IF( (VLOOKUP(B73,K:N,3,FALSE)) < C73, "X", "" ), "X") )
A74: DEL | B74: Brugui | C74: 45949 | D74: 1500001 | E74: =IF(B74="","",IFERROR( IF( (VLOOKUP(B74,K:N,3,FALSE)) < C74, "X", "" ), "X") ) -> X
...

Sheet yandrak
A1: Indice | B1: yandrak
A2: Fichajes | K2: Ventas
A3: Posicion | B3: Jugador | C3: Fecha Compra | D3: Precio Compra | E3: Plantilla | K3: Posicion | L3: Jugador | M3: Fecha Venta | N3: Precio Venta | O3: Precio Compra | P3: Rentabilidad
A4: {=_xlfn._xlws.FILTER(Fichajes!C:C,Fichajes!G:G=B1)} -> DEF | B4: {=_xlfn._xlws.FILTER(Fichajes!B:B,Fichajes!G:G=B1)} -> Andrei | C4: {=_xlfn._xlws.FILTER(Fichajes!F:F,Fichajes!$G:$G=$B1)} -> 45872 | D4: {=_xlfn._xlws.FILTER(Fichajes!I:I,Fichajes!$G:$G=$B1)} -> 0 | E4: =IF(B4="","",IFERROR( IF( (VLOOKUP(B4,K:N,3,FALSE)) < C4, "X", "" ), "X") ) | K4: {=_xlfn._xlws.FILTER(Fichajes!B:B,Fichajes!$H:$H=B$1)} -> D. Duarte | L4: {=_xlfn._xlws.FILTER(Fichajes!C:C,Fichajes!$H:$H=B$1)} -> DEF | M4: {=_xlfn._xlws.FILTER(Fichajes!F:F,Fichajes!$H:$H=B$1)} -> 45874 | N4: {=_xlfn._xlws.FILTER(Fichajes!I:I,Fichajes!$H:$H=B$1)} -> 1167041 | O4: =IF(ISBLANK(N4),"",VLOOKUP(K4,B:D,3,FALSE)) -> 0 | P4: =IF(ISBLANK(N4),"",N4-O4) -> 1167041
A5: MED | B5: Blanco | C5: 45872 | D5: 0 | E5: =IF(B5="","",IFERROR( IF( (VLOOKUP(B5,K:N,3,FALSE)) < C5, "X", "" ), "X") ) | K5: Andrei | L5: DEF | M5: 45876 | N5: 14500000 | O5: =IF(ISBLANK(N5),"",VLOOKUP(K5,B:D,3,FALSE)) -> 0 | P5: =IF(ISBLANK(N5),"",N5-O5) -> 14500000
A6: POR | B6: Dimitrievski | C6: 45872 | D6: 0 | E6: =IF(B6="","",IFERROR( IF( (VLOOKUP(B6,K:N,3,FALSE)) < C6, "X", "" ), "X") ) | K6: Pablo Torre | L6: MED | M6: 45877 | N6: 10000000 | O6: =IF(ISBLANK(N6),"",VLOOKUP(K6,B:D,3,FALSE)) -> 0 | P6: =IF(ISBLANK(N6),"",N6-O6) -> 10000000
A7: DEF | B7: D. Duarte | C7: 45872 | D7: 0 | E7: =IF(B7="","",IFERROR( IF( (VLOOKUP(B7,K:N,3,FALSE)) < C7, "X", "" ), "X") ) | K7: Tsygankov | L7: DEL | M7: 45877 | N7: 18143367 | O7: =IF(ISBLANK(N7),"",VLOOKUP(K7,B:D,3,FALSE)) -> 0 | P7: =IF(ISBLANK(N7),"",N7-O7) -> 18143367
A8: DEF | B8: Foyth | C8: 45872 | D8: 0 | E8: =IF(B8="","",IFERROR( IF( (VLOOKUP(B8,K:N,3,FALSE)) < C8, "X", "" ), "X") ) | K8: Dimitrievski | L8: POR | M8: 45879 | N8: 6540521 | O8: =IF(ISBLANK(N8),"",VLOOKUP(K8,B:D,3,FALSE)) -> 0 | P8: =IF(ISBLANK(N8),"",N8-O8) -> 6540521
A9: DEL | B9: Giuliano | C9: 45872 | D9: 0 | E9: =IF(B9="","",IFERROR( IF( (VLOOKUP(B9,K:N,3,FALSE)) < C9, "X", "" ), "X") ) | K9: Moi Gómez | L9: MED | M9: 45879 | N9: 5807847 | O9: =IF(ISBLANK(N9),"",VLOOKUP(K9,B:D,3,FALSE)) -> 0 | P9: =IF(ISBLANK(N9),"",N9-O9) -> 5807847
A10: MED | B10: Javi Guerra | C10: 45872 | D10: 0 | E10: =IF(B10="","",IFERROR( IF( (VLOOKUP(B10,K:N,3,FALSE)) < C10, "X", "" ), "X") ) | K10: Pépé | L10: DEL | M10: 45886 | N10: 19282733 | O10: =IF(ISBLANK(N10),"",VLOOKUP(K10,B:D,3,FALSE)) -> 0 | P10: =IF(ISBLANK(N10),"",N10-O10) -> 19282733
A11: DEF | B11: Krejci | C11: 45872 | D11: 0 | E11: =IF(B11="","",IFERROR( IF( (VLOOKUP(B11,K:N,3,FALSE)) < C11, "X", "" ), "X") ) | K11: Blanco | L11: MED | M11: 45887 | N11: 11636446 | O11: =IF(ISBLANK(N11),"",VLOOKUP(K11,B:D,3,FALSE)) -> 0 | P11: =IF(ISBLANK(N11),"",N11-O11) -> 11636446
A12: MED | B12: Moi Gómez | C12: 45872 | D12: 0 | E12: =IF(B12="","",IFERROR( IF( (VLOOKUP(B12,K:N,3,FALSE)) < C12, "X", "" ), "X") ) | K12: Krejci | L12: DEF | M12: 45890 | N12: 6547216 | O12: =IF(ISBLANK(N12),"",VLOOKUP(K12,B:D,3,FALSE)) -> 0 | P12: =IF(ISBLANK(N12),"",N12-O12) -> 6547216
A13: MED | B13: Pablo Torre | C13: 45872 | D13: 0 | E13: =IF(B13="","",IFERROR( IF( (VLOOKUP(B13,K:N,3,FALSE)) < C13, "X", "" ), "X") ) | K13: Foyth | L13: DEF | M13: 45897 | N13: 27796533 | O13: =IF(ISBLANK(N13),"",VLOOKUP(K13,B:D,3,FALSE)) -> 0 | P13: =IF(ISBLANK(N13),"",N13-O13) -> 27796533
A14: DEL | B14: Pépé | C14: 45872 | D14: 0 | E14: =IF(B14="","",IFERROR( IF( (VLOOKUP(B14,K:N,3,FALSE)) < C14, "X", "" ), "X") ) | K14: Buchanan | L14: MED | M14: 45900 | N14: 10108420 | O14: =IF(ISBLANK(N14),"",VLOOKUP(K14,B:D,3,FALSE)) -> 5158826 | P14: =IF(ISBLANK(N14),"",N14-O14) -> 4949594
A15: MED | B15: Rioja | C15: 45872 | D15: 0 | E15: =IF(B15="","",IFERROR( IF( (VLOOKUP(B15,K:N,3,FALSE)) < C15, "X", "" ), "X") ) | K15: Giuliano | L15: DEL | M15: 45908 | N15: 40021696 | O15: =IF(ISBLANK(N15),"",VLOOKUP(K15,B:D,3,FALSE)) -> 0 | P15: =IF(ISBLANK(N15),"",N15-O15) -> 40021696
A16: DEF | B16: Ruggeri | C16: 45872 | D16: 0 | E16: =IF(B16="","",IFERROR( IF( (VLOOKUP(B16,K:N,3,FALSE)) < C16, "X", "" ), "X") ) | K16: Portu | L16: DEL | M16: 45910 | N16: 1306600 | O16: =IF(ISBLANK(N16),"",VLOOKUP(K16,B:D,3,FALSE)) -> 3212503 | P16: =IF(ISBLANK(N16),"",N16-O16) -> -1905903
... A35: MED | B35: Altimira | C35: 45916 | D35: 14285808 | E35: =IF(B35="","",IFERROR( IF( (VLOOKUP(B35,K:N,3,FALSE)) < C35, "X", "" ), "X") ) | K35: Peña | L35: POR | M35: 45931 | N35: 2259813 | O35: =IF(ISBLANK(N35),"",VLOOKUP(K35,B:D,3,FALSE)) -> 2225124 | P35: =IF(ISBLANK(N35),"",N35-O35) -> 34689
A36: DEF | B36: Ristic | C36: 45916 | D36: 1000000 | K36: Oluwaseyi | L36: DEL | M36: 45931 | N36: 2929819 | O36: =IF(ISBLANK(N36),"",VLOOKUP(K36,B:D,3,FALSE)) -> 2856286 | P36: =IF(ISBLANK(N36),"",N36-O36) -> 73533
A37: DEF | B37: Boyomo | C37: 45917 | D37: 19778592 | K37: Koundé | L37: DEF | M37: 45933 | N37: 53854422 | O37: =IF(ISBLANK(N37),"",VLOOKUP(K37,B:D,3,FALSE)) -> 63323263 | P37: =IF(ISBLANK(N37),"",N37-O37) -> -9468841
A38: DEL | B38: Giuliano | C38: 45920 | D38: 42151996 | K38: Bellingham | L38: MED | M38: 45937 | N38: 81008927 | O38: =IF(ISBLANK(N38),"",VLOOKUP(K38,B:D,3,FALSE)) -> 78247575 | P38: =IF(ISBLANK(N38),"",N38-O38) -> 2761352
A39: MED | B39: Tchouaméni | C39: 45921 | D39: 60976487 | K39: Romero | L39: DEL | M39: 45938 | N39: 13987987 | O39: =IF(ISBLANK(N39),"",VLOOKUP(K39,B:D,3,FALSE)) -> 13987987 | P39: =IF(ISBLANK(N39),"",N39-O39) -> 0
A40: MED | B40: Guridi | C40: 45922 | D40: 2499999 | K40: Vinicius | L40: DEL | M40: 45945 | N40: 152239079 | O40: =IF(ISBLANK(N40),"",VLOOKUP(K40,B:D,3,FALSE)) -> 130000001 | P40: =IF(ISBLANK(N40),"",N40-O40) -> 22239078
A41: DEL | B41: Romero | C41: 45922 | D41: 13987987 | K41: Jauregizar | L41: MED | M41: 45949 | N41: 24476604 | O41: =IF(ISBLANK(N41),"",VLOOKUP(K41,B:D,3,FALSE)) -> 18099036 | P41: =IF(ISBLANK(N41),"",N41-O41) -> 6377568
A42: DEL | B42: Durán | C42: 45922 | D42: 1600000 | K42: Durán | L42: DEL | M42: 45952 | N42: 1600000 | O42: =IF(ISBLANK(N42),"",VLOOKUP(K42,B:D,3,FALSE)) -> 1600000 | P42: =IF(ISBLANK(N42),"",N42-O42) -> 0
A43: MED | B43: Bellingham | C43: 45923 | D43: 78247575 | K43: Juan Cruz | L43: DEF | M43: 45952 | N43: 2243833 | O43: =IF(ISBLANK(N43),"",VLOOKUP(K43,B:D,3,FALSE)) -> 2090983 | P43: =IF(ISBLANK(N43),"",N43-O43) -> 152850
A44: DEF | B44: A. Christensen | C44: 45924 | D44: 4110892 | K44: Romero | L44: DEF | M44: 45955 | N44: 16000000 | O44: =IF(ISBLANK(N44),"",VLOOKUP(K44,B:D,3,FALSE)) -> 13987987 | P44: =IF(ISBLANK(N44),"",N44-O44) -> 2012013
A45: POR | B45: Peña | C45: 45929 | D45: 2225124 | K45: Abde | L45: DEL | M45: 45959 | N45: 32239613 | O45: =IF(ISBLANK(N45),"",VLOOKUP(K45,B:D,3,FALSE)) -> 32239613 | P45: =IF(ISBLANK(N45),"",N45-O45) -> 0
A46: DEF | B46: Francés | C46: 45930 | D46: 1704077 | K46: Alejandro Rego | L46: DEF | M46: 45959 | N46: 526248 | O46: =IF(ISBLANK(N46),"",VLOOKUP(K46,B:D,3,FALSE)) -> 512739 | P46: =IF(ISBLANK(N46),"",N46-O46) -> 13509
A47: MED | B47: Jauregizar | C47: 45930 | D47: 18099036 | K47: Oyarzabal | L47: DEL | M47: 45959 | N47: 43160079 | O47: =IF(ISBLANK(N47),"",VLOOKUP(K47,B:D,3,FALSE)) -> 38294813 | P47: =IF(ISBLANK(N47),"",N47-O47) -> 4865266
A48: DEL | B48: Oluwaseyi | C48: 45930 | D48: 2856286 | K48: M. Alonso | L48: DEF | M48: 45960 | N48: 18644883 | O48: =IF(ISBLANK(N48),"",VLOOKUP(K48,B:D,3,FALSE)) -> 18644883 | P48: =IF(ISBLANK(N48),"",N48-O48) -> 0
A49: MED | B49: Roca | C49: 45930 | D49: 379084 | K49: Güler | L49: MED | M49: 45960 | N49: 122854925
A50: MED | B50: Guevara | C50: 45932 | D50: 896928 | K50: Aguado | L50: MED | M50: 45964 | N50: 1286806
A51: DEL | B51: Vinicius | C51: 45933 | D51: 130000001 | K51: Hancko | L51: DEF | M51: 45966 | N51: 20000000
A52: DEF | B52: Romero | C52: 45933 | D52: 16000000 | K52: Valjent | L52: DEF | M52: 45966 | N52: 7108000
A53: DEF | B53: Paredes | C53: 45935 | D53: 28504496 | K53: Eric García | L53: DEF | M53: 45967 | N53: 43923813
A54: DEF | B54: Alejandro Rego | C54: 45935 | D54: 512739 | K54: Romero | L54: DEL | M54: 45968 | N54: 7974814
A55: DEF | B55: Juan Cruz | C55: 45936 | D55: 2806143 | K55: Iglesias | L55: DEL | M55: 45973 | N55: 19552500
A56: DEF | B56: Sergio Gómez | C56: 45944 | D56: 6195456
A57: MED | B57: Güler | C57: 45945 | D57: 122854925
A58: DEL | B58: Abde | C58: 45945 | D58: 32239613
...

Sheet Shiquetito 9
A1: Indice | B1: Shiquetito 9
A2: Fichajes | K2: Ventas
A3: Posicion | B3: Jugador | C3: Fecha Compra | D3: Precio Compra | E3: Plantilla | K3: Posicion | L3: Jugador | M3: Fecha Venta | N3: Precio Venta | O3: Precio Compra | P3: Rentabilidad
A4: {=_xlfn._xlws.FILTER(Fichajes!C:C,Fichajes!G:G=B1)} -> POR | B4: {=_xlfn._xlws.FILTER(Fichajes!B:B,Fichajes!G:G=B1)} -> Aitor | C4: {=_xlfn._xlws.FILTER(Fichajes!F:F,Fichajes!$G:$G=$B1)} -> 45875 | D4: {=_xlfn._xlws.FILTER(Fichajes!I:I,Fichajes!$G:$G=$B1)} -> 0 | E4: =IF(B4="","",IFERROR( IF( (VLOOKUP(B4,K:N,3,FALSE)) < C4, "X", "" ), "X") ) -> X | K4: {=_xlfn._xlws.FILTER(Fichajes!B:B,Fichajes!$H:$H=B$1)} -> Endrick | L4: {=_xlfn._xlws.FILTER(Fichajes!C:C,Fichajes!$H:$H=B$1)} -> DEL | M4: {=_xlfn._xlws.FILTER(Fichajes!F:F,Fichajes!$H:$H=B$1)} -> 45881 | N4: {=_xlfn._xlws.FILTER(Fichajes!I:I,Fichajes!$H:$H=B$1)} -> 6324142 | O4: =IF(ISBLANK(N4),"",VLOOKUP(K4,B:D,3,FALSE)) -> 0 | P4: =IF(ISBLANK(N4),"",N4-O4) -> 6324142
A5: MED | B5: Almada | C5: 45875 | D5: 0 | E5: =IF(B5="","",IFERROR( IF( (VLOOKUP(B5,K:N,3,FALSE)) < C5, "X", "" ), "X") ) | K5: Miguel | L5: DEF | M5: 45881 | N5: 9729339 | O5: =IF(ISBLANK(N5),"",VLOOKUP(K5,B:D,3,FALSE)) -> 0 | P5: =IF(ISBLANK(N5),"",N5-O5) -> 9729339
A6: MED | B6: Almeida | C6: 45875 | D6: 0 | E6: =IF(B6="","",IFERROR( IF( (VLOOKUP(B6,K:N,3,FALSE)) < C6, "X", "" ), "X") ) -> X | K6: Rodrygo | L6: DEL | M6: 45881 | N6: 20644625 | O6: =IF(ISBLANK(N6),"",VLOOKUP(K6,B:D,3,FALSE)) -> 0 | P6: =IF(ISBLANK(N6),"",N6-O6) -> 20644625
A7: DEF | B7: D. Duarte | C7: 45875 | D7: 0 | E7: =IF(B7="","",IFERROR( IF( (VLOOKUP(B7,K:N,3,FALSE)) < C7, "X", "" ), "X") ) | K7: Almada | L7: MED | M7: 45889 | N7: 27002791 | O7: =IF(ISBLANK(N7),"",VLOOKUP(K7,B:D,3,FALSE)) -> 0 | P7: =IF(ISBLANK(N7),"",N7-O7) -> 27002791
A8: DEL | B8: Endrick | C8: 45875 | D8: 0 | E8: =IF(B8="","",IFERROR( IF( (VLOOKUP(B8,K:N,3,FALSE)) < C8, "X", "" ), "X") ) | K8: Raba | L8: DEL | M8: 45889 | N8: 13741840 | O8: =IF(ISBLANK(N8),"",VLOOKUP(K8,B:D,3,FALSE)) -> 0 | P8: =IF(ISBLANK(N8),"",N8-O8) -> 13741840
A9: DEF | B9: Hancko | C9: 45875 | D9: 0 | E9: =IF(B9="","",IFERROR( IF( (VLOOKUP(B9,K:N,3,FALSE)) < C9, "X", "" ), "X") ) | K9: Riquelme | L9: MED | M9: 45889 | N9: 17158711 | O9: =IF(ISBLANK(N9),"",VLOOKUP(K9,B:D,3,FALSE)) -> 0 | P9: =IF(ISBLANK(N9),"",N9-O9) -> 17158711
A10: DEF | B10: Miguel | C10: 45875 | D10: 0 | E10: =IF(B10="","",IFERROR( IF( (VLOOKUP(B10,K:N,3,FALSE)) < C10, "X", "" ), "X") ) | K10: Parejo | L10: MED | M10: 45894 | N10: 12353847 | O10: =IF(ISBLANK(N10),"",VLOOKUP(K10,B:D,3,FALSE)) -> 0 | P10: =IF(ISBLANK(N10),"",N10-O10) -> 12353847
A11: MED | B11: Moleiro | C11: 45875 | D11: 0 | E11: =IF(B11="","",IFERROR( IF( (VLOOKUP(B11,K:N,3,FALSE)) < C11, "X", "" ), "X") ) | K11: Ejuke | L11: DEL | M11: 45896 | N11: 4000000 | O11: =IF(ISBLANK(N11),"",VLOOKUP(K11,B:D,3,FALSE)) -> 4000000 | P11: =IF(ISBLANK(N11),"",N11-O11) -> 0
A12: DEF | B12: Espino | C12: 45875 | D12: 3896588 | E12: =IF(B12="","",IFERROR( IF( (VLOOKUP(B12,K:N,3,FALSE)) < C12, "X", "" ), "X") ) -> X | K12: Agoume | L12: MED | M12: 45897 | N12: 7238909 | O12: =IF(ISBLANK(N12),"",VLOOKUP(K12,B:D,3,FALSE)) -> 7238909 | P12: =IF(ISBLANK(N12),"",N12-O12) -> 0
A13: DEF | B13: Paredes | C13: 45875 | D13: 0 | E13: =IF(B13="","",IFERROR( IF( (VLOOKUP(B13,K:N,3,FALSE)) < C13, "X", "" ), "X") ) | K13: Hancko | L13: DEF | M13: 45897 | N13: 34298293 | O13: =IF(ISBLANK(N13),"",VLOOKUP(K13,B:D,3,FALSE)) -> 0 | P13: =IF(ISBLANK(N13),"",N13-O13) -> 34298293
A14: MED | B14: Parejo | C14: 45875 | D14: 0 | E14: =IF(B14="","",IFERROR( IF( (VLOOKUP(B14,K:N,3,FALSE)) < C14, "X", "" ), "X") ) | K14: Iglesias | L14: DEF | M14: 45897 | N14: 2369904 | O14: =IF(ISBLANK(N14),"",VLOOKUP(K14,B:D,3,FALSE)) -> 2100858 | P14: =IF(ISBLANK(N14),"",N14-O14) -> 269046
A15: DEL | B15: Raba | C15: 45875 | D15: 0 | E15: =IF(B15="","",IFERROR( IF( (VLOOKUP(B15,K:N,3,FALSE)) < C15, "X", "" ), "X") ) | K15: Paredes | L15: DEF | M15: 45900 | N15: 17925060 | O15: =IF(ISBLANK(N15),"",VLOOKUP(K15,B:D,3,FALSE)) -> 0 | P15: =IF(ISBLANK(N15),"",N15-O15) -> 17925060
A16: MED | B16: Riquelme | C16: 45875 | D16: 0 | E16: =IF(B16="","",IFERROR( IF( (VLOOKUP(B16,K:N,3,FALSE)) < C16, "X", "" ), "X") ) | K16: D. Duarte | L16: DEF | M16: 45906 | N16: 1672958 | O16: =IF(ISBLANK(N16),"",VLOOKUP(K16,B:D,3,FALSE)) -> 0 | P16: =IF(ISBLANK(N16),"",N16-O16) -> 1672958
... A37: MED | B37: Oriol Rey | C37: 45920 | D37: 1800000 | E37: =IF(B37="","",IFERROR( IF( (VLOOKUP(B37,K:N,3,FALSE)) < C37, "X", "" ), "X") ) -> X | K37: Raúl García | L37: DEL | M37: 45967 | N37: 4605484 | O37: =IF(ISBLANK(N37),"",VLOOKUP(K37,B:D,3,FALSE)) -> 4605484 | P37: =IF(ISBLANK(N37),"",N37-O37) -> 0
A38: MED | B38: Moriba | C38: 45922 | D38: 5284286 | E38: =IF(B38="","",IFERROR( IF( (VLOOKUP(B38,K:N,3,FALSE)) < C38, "X", "" ), "X") ) -> X | O38: =IF(ISBLANK(N38),"",VLOOKUP(K38,B:D,3,FALSE)) | P38: =IF(ISBLANK(N38),"",N38-O38)
A39: MED | B39: Pathé Ciss | C39: 45922 | D39: 11000010 | E39: =IF(B39="","",IFERROR( IF( (VLOOKUP(B39,K:N,3,FALSE)) < C39, "X", "" ), "X") ) | O39: =IF(ISBLANK(N39),"",VLOOKUP(K39,B:D,3,FALSE)) | P39: =IF(ISBLANK(N39),"",N39-O39)
A40: DEL | B40: Bryan Gil | C40: 45926 | D40: 16680850 | E40: =IF(B40="","",IFERROR( IF( (VLOOKUP(B40,K:N,3,FALSE)) < C40, "X", "" ), "X") ) -> X | O40: =IF(ISBLANK(N40),"",VLOOKUP(K40,B:D,3,FALSE)) | P40: =IF(ISBLANK(N40),"",N40-O40)
A41: DEL | B41: Rodrygo | C41: 45926 | D41: 16680750 | E41: =IF(B41="","",IFERROR( IF( (VLOOKUP(B41,K:N,3,FALSE)) < C41, "X", "" ), "X") ) -> X | O41: =IF(ISBLANK(N41),"",VLOOKUP(K41,B:D,3,FALSE)) | P41: =IF(ISBLANK(N41),"",N41-O41)
A42: DEF | B42: Lenglet | C42: 45928 | D42: 10185880 | E42: =IF(B42="","",IFERROR( IF( (VLOOKUP(B42,K:N,3,FALSE)) < C42, "X", "" ), "X") ) -> X | O42: =IF(ISBLANK(N42),"",VLOOKUP(K42,B:D,3,FALSE)) | P42: =IF(ISBLANK(N42),"",N42-O42)
A43: POR | B43: Radu | C43: 45928 | D43: 12668085 | E43: =IF(B43="","",IFERROR( IF( (VLOOKUP(B43,K:N,3,FALSE)) < C43, "X", "" ), "X") ) | O43: =IF(ISBLANK(N43),"",VLOOKUP(K43,B:D,3,FALSE)) | P43: =IF(ISBLANK(N43),"",N43-O43)
A44: DEL | B44: Morales | C44: 45942 | D44: 8396857 | E44: =IF(B44="","",IFERROR( IF( (VLOOKUP(B44,K:N,3,FALSE)) < C44, "X", "" ), "X") ) -> X | O44: =IF(ISBLANK(N44),"",VLOOKUP(K44,B:D,3,FALSE)) | P44: =IF(ISBLANK(N44),"",N44-O44)
A45: DEL | B45: Mastantuono | C45: 45942 | D45: 53968850 | E45: =IF(B45="","",IFERROR( IF( (VLOOKUP(B45,K:N,3,FALSE)) < C45, "X", "" ), "X") ) -> X | O45: =IF(ISBLANK(N45),"",VLOOKUP(K45,B:D,3,FALSE)) | P45: =IF(ISBLANK(N45),"",N45-O45)
A46: MED | B46: Sow | C46: 45944 | D46: 2213460 | E46: =IF(B46="","",IFERROR( IF( (VLOOKUP(B46,K:N,3,FALSE)) < C46, "X", "" ), "X") ) | O46: =IF(ISBLANK(N46),"",VLOOKUP(K46,B:D,3,FALSE)) | P46: =IF(ISBLANK(N46),"",N46-O46)
A47: MED | B47: Hugo Álvarez | C47: 45944 | D47: 6700000 | E47: =IF(B47="","",IFERROR( IF( (VLOOKUP(B47,K:N,3,FALSE)) < C47, "X", "" ), "X") ) -> X | O47: =IF(ISBLANK(N47),"",VLOOKUP(K47,B:D,3,FALSE)) | P47: =IF(ISBLANK(N47),"",N47-O47)
A48: MED | B48: Edu Expósito | C48: 45944 | D48: 22875987 | E48: =IF(B48="","",IFERROR( IF( (VLOOKUP(B48,K:N,3,FALSE)) < C48, "X", "" ), "X") ) | O48: =IF(ISBLANK(N48),"",VLOOKUP(K48,B:D,3,FALSE)) | P48: =IF(ISBLANK(N48),"",N48-O48)
A49: DEL | B49: Mikautadze | C49: 45944 | D49: 45100000
A50: DEF | B50: Laporte | C50: 45944 | D50: 35533525
A51: DEF | B51: Iglesias | C51: 45960 | D51: 2369904
A52: DEL | B52: Dolan | C52: 45960 | D52: 8465783
A53: POR | B53: Ryan | C53: 45960 | D53: 10000000
A54: DEF | B54: M. Alonso | C54: 45960 | D54: 18644883
A55: DEF | B55: Ratiu | C55: 45960 | D55: 28741587
A56: MED | B56: Valentín | C56: 45967 | D56: 5689088
A57: MED | B57: Thomas | C57: 45971 | D57: 4668380

Sheet davidcdl10
A1: Indice | B1: davidcdl10
A2: Fichajes | K2: Ventas
A3: Posicion | B3: Jugador | C3: Fecha Compra | D3: Precio Compra | E3: Plantilla | K3: Posicion | L3: Jugador | N3: Fecha Venta | O3: Precio Venta | P3: Precio Compra | Q3: Rentabilidad | R3: Rentabilidad Fichajes
A4: {=_xlfn._xlws.FILTER(Fichajes!C:C,Fichajes!G:G=B1)} -> MED | B4: {=_xlfn._xlws.FILTER(Fichajes!B:B,Fichajes!G:G=B1)} -> Almeida | C4: {=_xlfn._xlws.FILTER(Fichajes!F:F,Fichajes!$G:$G=$B1)} -> 45872 | D4: {=_xlfn._xlws.FILTER(Fichajes!I:I,Fichajes!$G:$G=$B1)} -> 0 | E4: =IF(B4="","",IFERROR( IF( (VLOOKUP(B4,K:O,3,FALSE)) < C4, "X", "" ), "X") ) | K4: {=_xlfn._xlws.FILTER(Fichajes!B:B,Fichajes!$H:$H=B$1)} -> Almeida | L4: {=_xlfn._xlws.FILTER(Fichajes!C:C,Fichajes!$H:$H=B$1)} -> MED | M4: {=_xlfn._xlws.FILTER(Fichajes!G:G,Fichajes!$H:$H=B$1)} -> Liga | N4: {=_xlfn._xlws.FILTER(Fichajes!F:F,Fichajes!$H:$H=B$1)} -> 45873 | O4: {=_xlfn._xlws.FILTER(Fichajes!I:I,Fichajes!$H:$H=B$1)} -> 8942183 | P4: =IF(ISBLANK(O4),"",VLOOKUP(K4,B:D,3,FALSE)) -> 0 | Q4: =IF(ISBLANK(O4),"",O4-P4) -> 8942183 | R4: =IF(P4=0,0,Q4) -> 0
A5: DEF | B5: Bade | C5: 45872 | D5: 0 | E5: =IF(B5="","",IFERROR( IF( (VLOOKUP(B5,K:O,3,FALSE)) < C5, "X", "" ), "X") ) | K5: Parejo | L5: MED | M5: Liga | N5: 45873 | O5: 16272690 | P5: =IF(ISBLANK(O5),"",VLOOKUP(K5,B:D,3,FALSE)) -> 0 | Q5: =IF(ISBLANK(O5),"",O5-P5) -> 16272690 | R5: =IF(P5=0,0,Q5) -> 0
A6: DEF | B6: Boyomo | C6: 45872 | D6: 0 | E6: =IF(B6="","",IFERROR( IF( (VLOOKUP(B6,K:O,3,FALSE)) < C6, "X", "" ), "X") ) | K6: Bade | L6: DEF | M6: Liga | N6: 45885 | O6: 11998476 | P6: =IF(ISBLANK(O6),"",VLOOKUP(K6,B:D,3,FALSE)) -> 0 | Q6: =IF(ISBLANK(O6),"",O6-P6) -> 11998476 | R6: =IF(P6=0,0,Q6) -> 0
A7: DEL | B7: De Frutos | C7: 45872 | D7: 0 | E7: =IF(B7="","",IFERROR( IF( (VLOOKUP(B7,K:O,3,FALSE)) < C7, "X", "" ), "X") ) | K7: De Frutos | L7: DEL | M7: Desteban19 | N7: 45886 | O7: 13861683 | P7: =IF(ISBLANK(O7),"",VLOOKUP(K7,B:D,3,FALSE)) -> 0 | Q7: =IF(ISBLANK(O7),"",O7-P7) -> 13861683 | R7: =IF(P7=0,0,Q7) -> 0
A8: DEF | B8: De la Fuente | C8: 45872 | D8: 0 | E8: =IF(B8="","",IFERROR( IF( (VLOOKUP(B8,K:O,3,FALSE)) < C8, "X", "" ), "X") ) | K8: Dmitrovic | L8: POR | M8: FC Recreativo de Juerga | N8: 45887 | O8: 11146825 | P8: =IF(ISBLANK(O8),"",VLOOKUP(K8,B:D,3,FALSE)) -> 0 | Q8: =IF(ISBLANK(O8),"",O8-P8) -> 11146825 | R8: =IF(P8=0,0,Q8) -> 0
